2020-10-19 04:06:02,686	[INFO]	/usr/local/lib/python3.8/site-packages/django/utils/autoreload.py(Line:612)	Watching for file changes with StatReloader
2020-10-19 04:06:51,903	[INFO]	/usr/local/lib/python3.8/site-packages/django/utils/autoreload.py(Line:612)	Watching for file changes with StatReloader
2020-10-19 04:09:08,993	[INFO]	/usr/local/lib/python3.8/site-packages/django/utils/autoreload.py(Line:612)	Watching for file changes with StatReloader
2020-10-19 04:35:07,492	[INFO]	/usr/local/lib/python3.8/site-packages/django/utils/autoreload.py(Line:612)	Watching for file changes with StatReloader
2020-10-19 04:47:36,755	[INFO]	/usr/local/lib/python3.8/site-packages/django/utils/autoreload.py(Line:612)	Watching for file changes with StatReloader
2020-10-19 04:47:57,533	[INFO]	/usr/local/lib/python3.8/site-packages/django/core/servers/basehttp.py(Line:157)	"GET /tech/ HTTP/1.1" 200 6908
2020-10-19 04:47:57,594	[INFO]	/usr/local/lib/python3.8/site-packages/django/core/servers/basehttp.py(Line:157)	"GET /static/demo/demo.css HTTP/1.1" 304 0
2020-10-19 04:47:57,595	[INFO]	/usr/local/lib/python3.8/site-packages/django/core/servers/basehttp.py(Line:157)	"GET /static/css/material-kit.css HTTP/1.1" 304 0
2020-10-19 04:47:57,600	[INFO]	/usr/local/lib/python3.8/site-packages/django/core/servers/basehttp.py(Line:157)	"GET /static/css/my.css HTTP/1.1" 304 0
2020-10-19 04:47:57,601	[INFO]	/usr/local/lib/python3.8/site-packages/django/core/servers/basehttp.py(Line:157)	"GET /static/js/core/jquery.min.js HTTP/1.1" 304 0
2020-10-19 04:47:57,605	[INFO]	/usr/local/lib/python3.8/site-packages/django/core/servers/basehttp.py(Line:157)	"GET /static/js/core/popper.min.js HTTP/1.1" 304 0
2020-10-19 04:47:57,607	[INFO]	/usr/local/lib/python3.8/site-packages/django/core/servers/basehttp.py(Line:157)	"GET /static/js/core/bootstrap-material-design.min.js HTTP/1.1" 304 0
2020-10-19 04:47:57,616	[INFO]	/usr/local/lib/python3.8/site-packages/django/core/servers/basehttp.py(Line:157)	"GET /static/js/plugins/moment.min.js HTTP/1.1" 304 0
2020-10-19 04:47:57,617	[INFO]	/usr/local/lib/python3.8/site-packages/django/core/servers/basehttp.py(Line:157)	"GET /static/js/my/get_model.js HTTP/1.1" 304 0
2020-10-19 04:47:57,618	[INFO]	/usr/local/lib/python3.8/site-packages/django/core/servers/basehttp.py(Line:157)	"GET /static/js/my/get_calculate.js HTTP/1.1" 304 0
2020-10-19 04:47:57,619	[INFO]	/usr/local/lib/python3.8/site-packages/django/core/servers/basehttp.py(Line:157)	"GET /static/js/plugins/bootstrap-datetimepicker.js HTTP/1.1" 304 0
2020-10-19 04:47:57,621	[INFO]	/usr/local/lib/python3.8/site-packages/django/core/servers/basehttp.py(Line:157)	"GET /static/js/plugins/nouislider.min.js HTTP/1.1" 304 0
2020-10-19 04:47:57,654	[INFO]	/usr/local/lib/python3.8/site-packages/django/core/servers/basehttp.py(Line:157)	"GET /static/js/material-kit.js HTTP/1.1" 304 0
2020-10-19 04:47:57,688	[INFO]	/usr/local/lib/python3.8/site-packages/django/core/servers/basehttp.py(Line:157)	"GET /static/img/profile_city.jpg HTTP/1.1" 304 0
2020-10-19 04:47:57,753	[INFO]	/usr/local/lib/python3.8/site-packages/django/core/servers/basehttp.py(Line:157)	"GET /static/img/favicon.png HTTP/1.1" 200 2761
2020-10-19 04:51:54,825	[INFO]	/usr/local/lib/python3.8/site-packages/django/utils/autoreload.py(Line:612)	Watching for file changes with StatReloader
2020-10-19 04:52:07,714	[INFO]	/usr/local/lib/python3.8/site-packages/django/utils/autoreload.py(Line:236)	/code/MLkit/settings.py changed, reloading.
2020-10-19 04:52:08,525	[INFO]	/usr/local/lib/python3.8/site-packages/django/utils/autoreload.py(Line:612)	Watching for file changes with StatReloader
2020-10-19 04:52:19,755	[ERROR]	/usr/local/lib/python3.8/site-packages/django/utils/log.py(Line:224)	Internal Server Error: /tech/
Traceback (most recent call last):
  File "/usr/local/lib/python3.8/site-packages/django/db/backends/utils.py", line 84, in _execute
    return self.cursor.execute(sql, params)
psycopg2.errors.UndefinedTable: relation "tech_mlmodel" does not exist
LINE 1: ... "tech_mlmodel"."mdl", "tech_mlmodel"."code" FROM "tech_mlmo...
                                                             ^


The above exception was the direct cause of the following exception:

Traceback (most recent call last):
  File "/usr/local/lib/python3.8/site-packages/django/core/handlers/exception.py", line 47, in inner
    response = get_response(request)
  File "/usr/local/lib/python3.8/site-packages/django/core/handlers/base.py", line 179, in _get_response
    response = wrapped_callback(request, *callback_args, **callback_kwargs)
  File "/code/tech/views.py", line 24, in index
    return render(request, "tech/index.html",{
  File "/usr/local/lib/python3.8/site-packages/django/shortcuts.py", line 19, in render
    content = loader.render_to_string(template_name, context, request, using=using)
  File "/usr/local/lib/python3.8/site-packages/django/template/loader.py", line 62, in render_to_string
    return template.render(context, request)
  File "/usr/local/lib/python3.8/site-packages/django/template/backends/django.py", line 61, in render
    return self.template.render(context)
  File "/usr/local/lib/python3.8/site-packages/django/template/base.py", line 170, in render
    return self._render(context)
  File "/usr/local/lib/python3.8/site-packages/django/template/base.py", line 162, in _render
    return self.nodelist.render(context)
  File "/usr/local/lib/python3.8/site-packages/django/template/base.py", line 938, in render
    bit = node.render_annotated(context)
  File "/usr/local/lib/python3.8/site-packages/django/template/base.py", line 905, in render_annotated
    return self.render(context)
  File "/usr/local/lib/python3.8/site-packages/django/template/loader_tags.py", line 150, in render
    return compiled_parent._render(context)
  File "/usr/local/lib/python3.8/site-packages/django/template/base.py", line 162, in _render
    return self.nodelist.render(context)
  File "/usr/local/lib/python3.8/site-packages/django/template/base.py", line 938, in render
    bit = node.render_annotated(context)
  File "/usr/local/lib/python3.8/site-packages/django/template/base.py", line 905, in render_annotated
    return self.render(context)
  File "/usr/local/lib/python3.8/site-packages/django/template/loader_tags.py", line 62, in render
    result = block.nodelist.render(context)
  File "/usr/local/lib/python3.8/site-packages/django/template/base.py", line 938, in render
    bit = node.render_annotated(context)
  File "/usr/local/lib/python3.8/site-packages/django/template/base.py", line 905, in render_annotated
    return self.render(context)
  File "/usr/local/lib/python3.8/site-packages/django/template/defaulttags.py", line 168, in render
    len_values = len(values)
  File "/usr/local/lib/python3.8/site-packages/django/db/models/query.py", line 269, in __len__
    self._fetch_all()
  File "/usr/local/lib/python3.8/site-packages/django/db/models/query.py", line 1303, in _fetch_all
    self._result_cache = list(self._iterable_class(self))
  File "/usr/local/lib/python3.8/site-packages/django/db/models/query.py", line 53, in __iter__
    results = compiler.execute_sql(chunked_fetch=self.chunked_fetch, chunk_size=self.chunk_size)
  File "/usr/local/lib/python3.8/site-packages/django/db/models/sql/compiler.py", line 1156, in execute_sql
    cursor.execute(sql, params)
  File "/usr/local/lib/python3.8/site-packages/django/db/backends/utils.py", line 98, in execute
    return super().execute(sql, params)
  File "/usr/local/lib/python3.8/site-packages/django/db/backends/utils.py", line 66, in execute
    return self._execute_with_wrappers(sql, params, many=False, executor=self._execute)
  File "/usr/local/lib/python3.8/site-packages/django/db/backends/utils.py", line 75, in _execute_with_wrappers
    return executor(sql, params, many, context)
  File "/usr/local/lib/python3.8/site-packages/django/db/backends/utils.py", line 84, in _execute
    return self.cursor.execute(sql, params)
  File "/usr/local/lib/python3.8/site-packages/django/db/utils.py", line 90, in __exit__
    raise dj_exc_value.with_traceback(traceback) from exc_value
  File "/usr/local/lib/python3.8/site-packages/django/db/backends/utils.py", line 84, in _execute
    return self.cursor.execute(sql, params)
django.db.utils.ProgrammingError: relation "tech_mlmodel" does not exist
LINE 1: ... "tech_mlmodel"."mdl", "tech_mlmodel"."code" FROM "tech_mlmo...
                                                             ^

2020-10-19 04:52:19,955	[ERROR]	/usr/local/lib/python3.8/site-packages/django/core/servers/basehttp.py(Line:157)	"GET /tech/ HTTP/1.1" 500 192359
2020-10-19 04:55:11,039	[ERROR]	/usr/local/lib/python3.8/site-packages/django/utils/log.py(Line:224)	Internal Server Error: /tech/
Traceback (most recent call last):
  File "/usr/local/lib/python3.8/site-packages/django/db/backends/utils.py", line 84, in _execute
    return self.cursor.execute(sql, params)
psycopg2.errors.UndefinedTable: relation "tech_mlmodel" does not exist
LINE 1: ... "tech_mlmodel"."mdl", "tech_mlmodel"."code" FROM "tech_mlmo...
                                                             ^


The above exception was the direct cause of the following exception:

Traceback (most recent call last):
  File "/usr/local/lib/python3.8/site-packages/django/core/handlers/exception.py", line 47, in inner
    response = get_response(request)
  File "/usr/local/lib/python3.8/site-packages/django/core/handlers/base.py", line 179, in _get_response
    response = wrapped_callback(request, *callback_args, **callback_kwargs)
  File "/code/tech/views.py", line 24, in index
    return render(request, "tech/index.html",{
  File "/usr/local/lib/python3.8/site-packages/django/shortcuts.py", line 19, in render
    content = loader.render_to_string(template_name, context, request, using=using)
  File "/usr/local/lib/python3.8/site-packages/django/template/loader.py", line 62, in render_to_string
    return template.render(context, request)
  File "/usr/local/lib/python3.8/site-packages/django/template/backends/django.py", line 61, in render
    return self.template.render(context)
  File "/usr/local/lib/python3.8/site-packages/django/template/base.py", line 170, in render
    return self._render(context)
  File "/usr/local/lib/python3.8/site-packages/django/template/base.py", line 162, in _render
    return self.nodelist.render(context)
  File "/usr/local/lib/python3.8/site-packages/django/template/base.py", line 938, in render
    bit = node.render_annotated(context)
  File "/usr/local/lib/python3.8/site-packages/django/template/base.py", line 905, in render_annotated
    return self.render(context)
  File "/usr/local/lib/python3.8/site-packages/django/template/loader_tags.py", line 150, in render
    return compiled_parent._render(context)
  File "/usr/local/lib/python3.8/site-packages/django/template/base.py", line 162, in _render
    return self.nodelist.render(context)
  File "/usr/local/lib/python3.8/site-packages/django/template/base.py", line 938, in render
    bit = node.render_annotated(context)
  File "/usr/local/lib/python3.8/site-packages/django/template/base.py", line 905, in render_annotated
    return self.render(context)
  File "/usr/local/lib/python3.8/site-packages/django/template/loader_tags.py", line 62, in render
    result = block.nodelist.render(context)
  File "/usr/local/lib/python3.8/site-packages/django/template/base.py", line 938, in render
    bit = node.render_annotated(context)
  File "/usr/local/lib/python3.8/site-packages/django/template/base.py", line 905, in render_annotated
    return self.render(context)
  File "/usr/local/lib/python3.8/site-packages/django/template/defaulttags.py", line 168, in render
    len_values = len(values)
  File "/usr/local/lib/python3.8/site-packages/django/db/models/query.py", line 269, in __len__
    self._fetch_all()
  File "/usr/local/lib/python3.8/site-packages/django/db/models/query.py", line 1303, in _fetch_all
    self._result_cache = list(self._iterable_class(self))
  File "/usr/local/lib/python3.8/site-packages/django/db/models/query.py", line 53, in __iter__
    results = compiler.execute_sql(chunked_fetch=self.chunked_fetch, chunk_size=self.chunk_size)
  File "/usr/local/lib/python3.8/site-packages/django/db/models/sql/compiler.py", line 1156, in execute_sql
    cursor.execute(sql, params)
  File "/usr/local/lib/python3.8/site-packages/django/db/backends/utils.py", line 98, in execute
    return super().execute(sql, params)
  File "/usr/local/lib/python3.8/site-packages/django/db/backends/utils.py", line 66, in execute
    return self._execute_with_wrappers(sql, params, many=False, executor=self._execute)
  File "/usr/local/lib/python3.8/site-packages/django/db/backends/utils.py", line 75, in _execute_with_wrappers
    return executor(sql, params, many, context)
  File "/usr/local/lib/python3.8/site-packages/django/db/backends/utils.py", line 84, in _execute
    return self.cursor.execute(sql, params)
  File "/usr/local/lib/python3.8/site-packages/django/db/utils.py", line 90, in __exit__
    raise dj_exc_value.with_traceback(traceback) from exc_value
  File "/usr/local/lib/python3.8/site-packages/django/db/backends/utils.py", line 84, in _execute
    return self.cursor.execute(sql, params)
django.db.utils.ProgrammingError: relation "tech_mlmodel" does not exist
LINE 1: ... "tech_mlmodel"."mdl", "tech_mlmodel"."code" FROM "tech_mlmo...
                                                             ^

2020-10-19 04:55:11,041	[ERROR]	/usr/local/lib/python3.8/site-packages/django/core/servers/basehttp.py(Line:157)	"GET /tech/ HTTP/1.1" 500 192359
2020-10-19 04:55:20,775	[INFO]	/usr/local/lib/python3.8/site-packages/django/core/servers/basehttp.py(Line:157)	"GET /tech/select_data HTTP/1.1" 200 7256
2020-10-19 04:55:20,823	[INFO]	/usr/local/lib/python3.8/site-packages/django/core/servers/basehttp.py(Line:157)	"GET /static/img/exam_img.jpg HTTP/1.1" 304 0
2020-10-19 04:55:24,858	[ERROR]	/usr/local/lib/python3.8/site-packages/django/utils/log.py(Line:224)	Internal Server Error: /tech/
Traceback (most recent call last):
  File "/usr/local/lib/python3.8/site-packages/django/db/backends/utils.py", line 84, in _execute
    return self.cursor.execute(sql, params)
psycopg2.errors.UndefinedTable: relation "tech_mlmodel" does not exist
LINE 1: ... "tech_mlmodel"."mdl", "tech_mlmodel"."code" FROM "tech_mlmo...
                                                             ^


The above exception was the direct cause of the following exception:

Traceback (most recent call last):
  File "/usr/local/lib/python3.8/site-packages/django/core/handlers/exception.py", line 47, in inner
    response = get_response(request)
  File "/usr/local/lib/python3.8/site-packages/django/core/handlers/base.py", line 179, in _get_response
    response = wrapped_callback(request, *callback_args, **callback_kwargs)
  File "/code/tech/views.py", line 24, in index
    return render(request, "tech/index.html",{
  File "/usr/local/lib/python3.8/site-packages/django/shortcuts.py", line 19, in render
    content = loader.render_to_string(template_name, context, request, using=using)
  File "/usr/local/lib/python3.8/site-packages/django/template/loader.py", line 62, in render_to_string
    return template.render(context, request)
  File "/usr/local/lib/python3.8/site-packages/django/template/backends/django.py", line 61, in render
    return self.template.render(context)
  File "/usr/local/lib/python3.8/site-packages/django/template/base.py", line 170, in render
    return self._render(context)
  File "/usr/local/lib/python3.8/site-packages/django/template/base.py", line 162, in _render
    return self.nodelist.render(context)
  File "/usr/local/lib/python3.8/site-packages/django/template/base.py", line 938, in render
    bit = node.render_annotated(context)
  File "/usr/local/lib/python3.8/site-packages/django/template/base.py", line 905, in render_annotated
    return self.render(context)
  File "/usr/local/lib/python3.8/site-packages/django/template/loader_tags.py", line 150, in render
    return compiled_parent._render(context)
  File "/usr/local/lib/python3.8/site-packages/django/template/base.py", line 162, in _render
    return self.nodelist.render(context)
  File "/usr/local/lib/python3.8/site-packages/django/template/base.py", line 938, in render
    bit = node.render_annotated(context)
  File "/usr/local/lib/python3.8/site-packages/django/template/base.py", line 905, in render_annotated
    return self.render(context)
  File "/usr/local/lib/python3.8/site-packages/django/template/loader_tags.py", line 62, in render
    result = block.nodelist.render(context)
  File "/usr/local/lib/python3.8/site-packages/django/template/base.py", line 938, in render
    bit = node.render_annotated(context)
  File "/usr/local/lib/python3.8/site-packages/django/template/base.py", line 905, in render_annotated
    return self.render(context)
  File "/usr/local/lib/python3.8/site-packages/django/template/defaulttags.py", line 168, in render
    len_values = len(values)
  File "/usr/local/lib/python3.8/site-packages/django/db/models/query.py", line 269, in __len__
    self._fetch_all()
  File "/usr/local/lib/python3.8/site-packages/django/db/models/query.py", line 1303, in _fetch_all
    self._result_cache = list(self._iterable_class(self))
  File "/usr/local/lib/python3.8/site-packages/django/db/models/query.py", line 53, in __iter__
    results = compiler.execute_sql(chunked_fetch=self.chunked_fetch, chunk_size=self.chunk_size)
  File "/usr/local/lib/python3.8/site-packages/django/db/models/sql/compiler.py", line 1156, in execute_sql
    cursor.execute(sql, params)
  File "/usr/local/lib/python3.8/site-packages/django/db/backends/utils.py", line 98, in execute
    return super().execute(sql, params)
  File "/usr/local/lib/python3.8/site-packages/django/db/backends/utils.py", line 66, in execute
    return self._execute_with_wrappers(sql, params, many=False, executor=self._execute)
  File "/usr/local/lib/python3.8/site-packages/django/db/backends/utils.py", line 75, in _execute_with_wrappers
    return executor(sql, params, many, context)
  File "/usr/local/lib/python3.8/site-packages/django/db/backends/utils.py", line 84, in _execute
    return self.cursor.execute(sql, params)
  File "/usr/local/lib/python3.8/site-packages/django/db/utils.py", line 90, in __exit__
    raise dj_exc_value.with_traceback(traceback) from exc_value
  File "/usr/local/lib/python3.8/site-packages/django/db/backends/utils.py", line 84, in _execute
    return self.cursor.execute(sql, params)
django.db.utils.ProgrammingError: relation "tech_mlmodel" does not exist
LINE 1: ... "tech_mlmodel"."mdl", "tech_mlmodel"."code" FROM "tech_mlmo...
                                                             ^

2020-10-19 04:55:24,861	[ERROR]	/usr/local/lib/python3.8/site-packages/django/core/servers/basehttp.py(Line:157)	"GET /tech/ HTTP/1.1" 500 192229
2020-10-19 04:55:27,350	[ERROR]	/usr/local/lib/python3.8/site-packages/django/utils/log.py(Line:224)	Internal Server Error: /tech/select_model
Traceback (most recent call last):
  File "/usr/local/lib/python3.8/site-packages/django/db/backends/utils.py", line 84, in _execute
    return self.cursor.execute(sql, params)
psycopg2.errors.UndefinedTable: relation "tech_mlmodel" does not exist
LINE 1: ... "tech_mlmodel"."mdl", "tech_mlmodel"."code" FROM "tech_mlmo...
                                                             ^


The above exception was the direct cause of the following exception:

Traceback (most recent call last):
  File "/usr/local/lib/python3.8/site-packages/django/core/handlers/exception.py", line 47, in inner
    response = get_response(request)
  File "/usr/local/lib/python3.8/site-packages/django/core/handlers/base.py", line 179, in _get_response
    response = wrapped_callback(request, *callback_args, **callback_kwargs)
  File "/code/tech/views.py", line 46, in select_model
    return render(request, "tech/index.html" ,{
  File "/usr/local/lib/python3.8/site-packages/django/shortcuts.py", line 19, in render
    content = loader.render_to_string(template_name, context, request, using=using)
  File "/usr/local/lib/python3.8/site-packages/django/template/loader.py", line 62, in render_to_string
    return template.render(context, request)
  File "/usr/local/lib/python3.8/site-packages/django/template/backends/django.py", line 61, in render
    return self.template.render(context)
  File "/usr/local/lib/python3.8/site-packages/django/template/base.py", line 170, in render
    return self._render(context)
  File "/usr/local/lib/python3.8/site-packages/django/template/base.py", line 162, in _render
    return self.nodelist.render(context)
  File "/usr/local/lib/python3.8/site-packages/django/template/base.py", line 938, in render
    bit = node.render_annotated(context)
  File "/usr/local/lib/python3.8/site-packages/django/template/base.py", line 905, in render_annotated
    return self.render(context)
  File "/usr/local/lib/python3.8/site-packages/django/template/loader_tags.py", line 150, in render
    return compiled_parent._render(context)
  File "/usr/local/lib/python3.8/site-packages/django/template/base.py", line 162, in _render
    return self.nodelist.render(context)
  File "/usr/local/lib/python3.8/site-packages/django/template/base.py", line 938, in render
    bit = node.render_annotated(context)
  File "/usr/local/lib/python3.8/site-packages/django/template/base.py", line 905, in render_annotated
    return self.render(context)
  File "/usr/local/lib/python3.8/site-packages/django/template/loader_tags.py", line 62, in render
    result = block.nodelist.render(context)
  File "/usr/local/lib/python3.8/site-packages/django/template/base.py", line 938, in render
    bit = node.render_annotated(context)
  File "/usr/local/lib/python3.8/site-packages/django/template/base.py", line 905, in render_annotated
    return self.render(context)
  File "/usr/local/lib/python3.8/site-packages/django/template/defaulttags.py", line 168, in render
    len_values = len(values)
  File "/usr/local/lib/python3.8/site-packages/django/db/models/query.py", line 269, in __len__
    self._fetch_all()
  File "/usr/local/lib/python3.8/site-packages/django/db/models/query.py", line 1303, in _fetch_all
    self._result_cache = list(self._iterable_class(self))
  File "/usr/local/lib/python3.8/site-packages/django/db/models/query.py", line 53, in __iter__
    results = compiler.execute_sql(chunked_fetch=self.chunked_fetch, chunk_size=self.chunk_size)
  File "/usr/local/lib/python3.8/site-packages/django/db/models/sql/compiler.py", line 1156, in execute_sql
    cursor.execute(sql, params)
  File "/usr/local/lib/python3.8/site-packages/django/db/backends/utils.py", line 98, in execute
    return super().execute(sql, params)
  File "/usr/local/lib/python3.8/site-packages/django/db/backends/utils.py", line 66, in execute
    return self._execute_with_wrappers(sql, params, many=False, executor=self._execute)
  File "/usr/local/lib/python3.8/site-packages/django/db/backends/utils.py", line 75, in _execute_with_wrappers
    return executor(sql, params, many, context)
  File "/usr/local/lib/python3.8/site-packages/django/db/backends/utils.py", line 84, in _execute
    return self.cursor.execute(sql, params)
  File "/usr/local/lib/python3.8/site-packages/django/db/utils.py", line 90, in __exit__
    raise dj_exc_value.with_traceback(traceback) from exc_value
  File "/usr/local/lib/python3.8/site-packages/django/db/backends/utils.py", line 84, in _execute
    return self.cursor.execute(sql, params)
django.db.utils.ProgrammingError: relation "tech_mlmodel" does not exist
LINE 1: ... "tech_mlmodel"."mdl", "tech_mlmodel"."code" FROM "tech_mlmo...
                                                             ^

2020-10-19 04:55:27,352	[ERROR]	/usr/local/lib/python3.8/site-packages/django/core/servers/basehttp.py(Line:157)	"GET /tech/select_model HTTP/1.1" 500 192450
2020-10-19 04:55:32,399	[ERROR]	/usr/local/lib/python3.8/site-packages/django/utils/log.py(Line:224)	Internal Server Error: /tech/calculation
Traceback (most recent call last):
  File "/usr/local/lib/python3.8/site-packages/django/db/backends/utils.py", line 84, in _execute
    return self.cursor.execute(sql, params)
psycopg2.errors.UndefinedTable: relation "tech_selectedmodel" does not exist
LINE 1: SELECT (1) AS "a" FROM "tech_selectedmodel" LIMIT 1
                               ^


The above exception was the direct cause of the following exception:

Traceback (most recent call last):
  File "/usr/local/lib/python3.8/site-packages/django/core/handlers/exception.py", line 47, in inner
    response = get_response(request)
  File "/usr/local/lib/python3.8/site-packages/django/core/handlers/base.py", line 179, in _get_response
    response = wrapped_callback(request, *callback_args, **callback_kwargs)
  File "/code/tech/views.py", line 79, in calculation
    if selectedModel.objects.exists() and selectedData.objects.exists() :
  File "/usr/local/lib/python3.8/site-packages/django/db/models/manager.py", line 85, in manager_method
    return getattr(self.get_queryset(), name)(*args, **kwargs)
  File "/usr/local/lib/python3.8/site-packages/django/db/models/query.py", line 809, in exists
    return self.query.has_results(using=self.db)
  File "/usr/local/lib/python3.8/site-packages/django/db/models/sql/query.py", line 535, in has_results
    return compiler.has_results()
  File "/usr/local/lib/python3.8/site-packages/django/db/models/sql/compiler.py", line 1126, in has_results
    return bool(self.execute_sql(SINGLE))
  File "/usr/local/lib/python3.8/site-packages/django/db/models/sql/compiler.py", line 1156, in execute_sql
    cursor.execute(sql, params)
  File "/usr/local/lib/python3.8/site-packages/django/db/backends/utils.py", line 98, in execute
    return super().execute(sql, params)
  File "/usr/local/lib/python3.8/site-packages/django/db/backends/utils.py", line 66, in execute
    return self._execute_with_wrappers(sql, params, many=False, executor=self._execute)
  File "/usr/local/lib/python3.8/site-packages/django/db/backends/utils.py", line 75, in _execute_with_wrappers
    return executor(sql, params, many, context)
  File "/usr/local/lib/python3.8/site-packages/django/db/backends/utils.py", line 84, in _execute
    return self.cursor.execute(sql, params)
  File "/usr/local/lib/python3.8/site-packages/django/db/utils.py", line 90, in __exit__
    raise dj_exc_value.with_traceback(traceback) from exc_value
  File "/usr/local/lib/python3.8/site-packages/django/db/backends/utils.py", line 84, in _execute
    return self.cursor.execute(sql, params)
django.db.utils.ProgrammingError: relation "tech_selectedmodel" does not exist
LINE 1: SELECT (1) AS "a" FROM "tech_selectedmodel" LIMIT 1
                               ^

2020-10-19 04:55:32,402	[ERROR]	/usr/local/lib/python3.8/site-packages/django/core/servers/basehttp.py(Line:157)	"GET /tech/calculation HTTP/1.1" 500 112282
2020-10-19 04:56:32,091	[INFO]	/usr/local/lib/python3.8/site-packages/django/utils/autoreload.py(Line:612)	Watching for file changes with StatReloader
2020-10-19 04:57:20,470	[INFO]	/usr/local/lib/python3.8/site-packages/django/utils/autoreload.py(Line:612)	Watching for file changes with StatReloader
2020-10-19 04:58:05,421	[INFO]	/usr/local/lib/python3.8/site-packages/django/utils/autoreload.py(Line:612)	Watching for file changes with StatReloader
2020-10-19 04:59:29,769	[INFO]	/usr/local/lib/python3.8/site-packages/django/utils/autoreload.py(Line:612)	Watching for file changes with StatReloader
2020-10-19 05:03:04,234	[INFO]	/usr/local/lib/python3.8/site-packages/django/core/servers/basehttp.py(Line:157)	"GET /tech/ HTTP/1.1" 200 6838
2020-10-19 05:04:27,769	[INFO]	/usr/local/lib/python3.8/site-packages/django/core/servers/basehttp.py(Line:157)	"GET /tech/select_data HTTP/1.1" 200 7256
2020-10-19 05:04:29,704	[INFO]	/usr/local/lib/python3.8/site-packages/django/core/servers/basehttp.py(Line:157)	"GET /tech/calculation HTTP/1.1" 302 0
2020-10-19 05:04:29,722	[INFO]	/usr/local/lib/python3.8/site-packages/django/core/servers/basehttp.py(Line:157)	"GET /tech/empty HTTP/1.1" 200 6425
2020-10-19 05:04:31,433	[INFO]	/usr/local/lib/python3.8/site-packages/django/core/servers/basehttp.py(Line:157)	"GET /tech/help HTTP/1.1" 200 7389
2020-10-19 05:08:31,541	[INFO]	/usr/local/lib/python3.8/site-packages/django/utils/autoreload.py(Line:612)	Watching for file changes with StatReloader
2020-10-19 05:08:47,842	[INFO]	/usr/local/lib/python3.8/site-packages/django/core/servers/basehttp.py(Line:157)	"GET /tech/help HTTP/1.1" 200 7389
2020-10-19 05:08:47,926	[INFO]	/usr/local/lib/python3.8/site-packages/django/core/servers/basehttp.py(Line:157)	"GET /static/img/favicon.png HTTP/1.1" 200 2761
2020-10-19 05:08:49,757	[INFO]	/usr/local/lib/python3.8/site-packages/django/core/servers/basehttp.py(Line:157)	"GET /tech/help HTTP/1.1" 200 7389
2020-10-19 05:08:50,818	[INFO]	/usr/local/lib/python3.8/site-packages/django/core/servers/basehttp.py(Line:157)	"GET /tech/ HTTP/1.1" 200 6838
2020-10-20 00:23:48,456	[INFO]	/usr/local/lib/python3.8/site-packages/django/utils/autoreload.py(Line:612)	Watching for file changes with StatReloader
2020-10-20 00:24:13,290	[INFO]	/usr/local/lib/python3.8/site-packages/django/core/servers/basehttp.py(Line:157)	"GET /tech/ HTTP/1.1" 200 6838
2020-10-20 00:26:51,925	[INFO]	/usr/local/lib/python3.8/site-packages/django/utils/autoreload.py(Line:612)	Watching for file changes with StatReloader
2020-10-20 00:27:05,492	[INFO]	/usr/local/lib/python3.8/site-packages/django/core/servers/basehttp.py(Line:157)	"GET /tech/ HTTP/1.1" 200 6838
2020-10-20 00:27:05,602	[INFO]	/usr/local/lib/python3.8/site-packages/django/core/servers/basehttp.py(Line:157)	"GET /static/img/favicon.png HTTP/1.1" 200 2761
2020-10-20 00:27:07,571	[INFO]	/usr/local/lib/python3.8/site-packages/django/core/servers/basehttp.py(Line:157)	"GET /tech/ HTTP/1.1" 200 6838
2020-10-20 00:27:08,537	[INFO]	/usr/local/lib/python3.8/site-packages/django/core/servers/basehttp.py(Line:157)	"GET /tech/select_model HTTP/1.1" 200 6838
2020-10-20 00:27:59,587	[INFO]	/usr/local/lib/python3.8/site-packages/django/utils/autoreload.py(Line:612)	Watching for file changes with StatReloader
2020-10-20 00:28:55,430	[ERROR]	/usr/local/lib/python3.8/site-packages/django/utils/log.py(Line:224)	Internal Server Error: /tech/select_model
Traceback (most recent call last):
  File "/usr/local/lib/python3.8/site-packages/django/db/backends/utils.py", line 84, in _execute
    return self.cursor.execute(sql, params)
psycopg2.errors.UndefinedTable: relation "tech_mlmodel" does not exist
LINE 1: ... "tech_mlmodel"."mdl", "tech_mlmodel"."code" FROM "tech_mlmo...
                                                             ^


The above exception was the direct cause of the following exception:

Traceback (most recent call last):
  File "/usr/local/lib/python3.8/site-packages/django/core/handlers/exception.py", line 47, in inner
    response = get_response(request)
  File "/usr/local/lib/python3.8/site-packages/django/core/handlers/base.py", line 179, in _get_response
    response = wrapped_callback(request, *callback_args, **callback_kwargs)
  File "/code/tech/views.py", line 46, in select_model
    return render(request, "tech/index.html" ,{
  File "/usr/local/lib/python3.8/site-packages/django/shortcuts.py", line 19, in render
    content = loader.render_to_string(template_name, context, request, using=using)
  File "/usr/local/lib/python3.8/site-packages/django/template/loader.py", line 62, in render_to_string
    return template.render(context, request)
  File "/usr/local/lib/python3.8/site-packages/django/template/backends/django.py", line 61, in render
    return self.template.render(context)
  File "/usr/local/lib/python3.8/site-packages/django/template/base.py", line 170, in render
    return self._render(context)
  File "/usr/local/lib/python3.8/site-packages/django/template/base.py", line 162, in _render
    return self.nodelist.render(context)
  File "/usr/local/lib/python3.8/site-packages/django/template/base.py", line 938, in render
    bit = node.render_annotated(context)
  File "/usr/local/lib/python3.8/site-packages/django/template/base.py", line 905, in render_annotated
    return self.render(context)
  File "/usr/local/lib/python3.8/site-packages/django/template/loader_tags.py", line 150, in render
    return compiled_parent._render(context)
  File "/usr/local/lib/python3.8/site-packages/django/template/base.py", line 162, in _render
    return self.nodelist.render(context)
  File "/usr/local/lib/python3.8/site-packages/django/template/base.py", line 938, in render
    bit = node.render_annotated(context)
  File "/usr/local/lib/python3.8/site-packages/django/template/base.py", line 905, in render_annotated
    return self.render(context)
  File "/usr/local/lib/python3.8/site-packages/django/template/loader_tags.py", line 62, in render
    result = block.nodelist.render(context)
  File "/usr/local/lib/python3.8/site-packages/django/template/base.py", line 938, in render
    bit = node.render_annotated(context)
  File "/usr/local/lib/python3.8/site-packages/django/template/base.py", line 905, in render_annotated
    return self.render(context)
  File "/usr/local/lib/python3.8/site-packages/django/template/defaulttags.py", line 168, in render
    len_values = len(values)
  File "/usr/local/lib/python3.8/site-packages/django/db/models/query.py", line 269, in __len__
    self._fetch_all()
  File "/usr/local/lib/python3.8/site-packages/django/db/models/query.py", line 1303, in _fetch_all
    self._result_cache = list(self._iterable_class(self))
  File "/usr/local/lib/python3.8/site-packages/django/db/models/query.py", line 53, in __iter__
    results = compiler.execute_sql(chunked_fetch=self.chunked_fetch, chunk_size=self.chunk_size)
  File "/usr/local/lib/python3.8/site-packages/django/db/models/sql/compiler.py", line 1156, in execute_sql
    cursor.execute(sql, params)
  File "/usr/local/lib/python3.8/site-packages/django/db/backends/utils.py", line 98, in execute
    return super().execute(sql, params)
  File "/usr/local/lib/python3.8/site-packages/django/db/backends/utils.py", line 66, in execute
    return self._execute_with_wrappers(sql, params, many=False, executor=self._execute)
  File "/usr/local/lib/python3.8/site-packages/django/db/backends/utils.py", line 75, in _execute_with_wrappers
    return executor(sql, params, many, context)
  File "/usr/local/lib/python3.8/site-packages/django/db/backends/utils.py", line 84, in _execute
    return self.cursor.execute(sql, params)
  File "/usr/local/lib/python3.8/site-packages/django/db/utils.py", line 90, in __exit__
    raise dj_exc_value.with_traceback(traceback) from exc_value
  File "/usr/local/lib/python3.8/site-packages/django/db/backends/utils.py", line 84, in _execute
    return self.cursor.execute(sql, params)
django.db.utils.ProgrammingError: relation "tech_mlmodel" does not exist
LINE 1: ... "tech_mlmodel"."mdl", "tech_mlmodel"."code" FROM "tech_mlmo...
                                                             ^

2020-10-20 00:28:55,449	[ERROR]	/usr/local/lib/python3.8/site-packages/django/core/servers/basehttp.py(Line:157)	"GET /tech/select_model HTTP/1.1" 500 192575
2020-10-20 00:29:09,230	[INFO]	/usr/local/lib/python3.8/site-packages/django/utils/autoreload.py(Line:612)	Watching for file changes with StatReloader
2020-10-20 00:30:13,814	[INFO]	/usr/local/lib/python3.8/site-packages/django/utils/autoreload.py(Line:612)	Watching for file changes with StatReloader
2020-10-20 00:43:25,387	[INFO]	/usr/local/lib/python3.8/site-packages/django/utils/autoreload.py(Line:612)	Watching for file changes with StatReloader
2020-10-20 00:43:38,589	[INFO]	/usr/local/lib/python3.8/site-packages/django/core/servers/basehttp.py(Line:157)	"GET /tech/ HTTP/1.1" 200 6838
2020-10-20 00:43:38,847	[INFO]	/usr/local/lib/python3.8/site-packages/django/core/servers/basehttp.py(Line:157)	"GET /static/img/favicon.png HTTP/1.1" 200 2761
2020-10-20 00:43:45,933	[INFO]	/usr/local/lib/python3.8/site-packages/django/core/servers/basehttp.py(Line:157)	"GET /tech/ HTTP/1.1" 200 6838
2020-10-20 00:43:46,011	[INFO]	/usr/local/lib/python3.8/site-packages/django/core/servers/basehttp.py(Line:157)	"GET /static/img/favicon.png HTTP/1.1" 200 2761
2020-10-20 00:50:09,311	[INFO]	/usr/local/lib/python3.8/site-packages/django/utils/autoreload.py(Line:612)	Watching for file changes with StatReloader
2020-10-20 00:53:53,367	[ERROR]	/usr/local/lib/python3.8/site-packages/django/utils/log.py(Line:224)	Internal Server Error: /tech/
Traceback (most recent call last):
  File "/usr/local/lib/python3.8/site-packages/django/db/backends/utils.py", line 84, in _execute
    return self.cursor.execute(sql, params)
psycopg2.errors.UndefinedTable: relation "tech_mlmodel" does not exist
LINE 1: ... "tech_mlmodel"."mdl", "tech_mlmodel"."code" FROM "tech_mlmo...
                                                             ^


The above exception was the direct cause of the following exception:

Traceback (most recent call last):
  File "/usr/local/lib/python3.8/site-packages/django/core/handlers/exception.py", line 47, in inner
    response = get_response(request)
  File "/usr/local/lib/python3.8/site-packages/django/core/handlers/base.py", line 179, in _get_response
    response = wrapped_callback(request, *callback_args, **callback_kwargs)
  File "/code/tech/views.py", line 24, in index
    return render(request, "tech/index.html",{
  File "/usr/local/lib/python3.8/site-packages/django/shortcuts.py", line 19, in render
    content = loader.render_to_string(template_name, context, request, using=using)
  File "/usr/local/lib/python3.8/site-packages/django/template/loader.py", line 62, in render_to_string
    return template.render(context, request)
  File "/usr/local/lib/python3.8/site-packages/django/template/backends/django.py", line 61, in render
    return self.template.render(context)
  File "/usr/local/lib/python3.8/site-packages/django/template/base.py", line 170, in render
    return self._render(context)
  File "/usr/local/lib/python3.8/site-packages/django/template/base.py", line 162, in _render
    return self.nodelist.render(context)
  File "/usr/local/lib/python3.8/site-packages/django/template/base.py", line 938, in render
    bit = node.render_annotated(context)
  File "/usr/local/lib/python3.8/site-packages/django/template/base.py", line 905, in render_annotated
    return self.render(context)
  File "/usr/local/lib/python3.8/site-packages/django/template/loader_tags.py", line 150, in render
    return compiled_parent._render(context)
  File "/usr/local/lib/python3.8/site-packages/django/template/base.py", line 162, in _render
    return self.nodelist.render(context)
  File "/usr/local/lib/python3.8/site-packages/django/template/base.py", line 938, in render
    bit = node.render_annotated(context)
  File "/usr/local/lib/python3.8/site-packages/django/template/base.py", line 905, in render_annotated
    return self.render(context)
  File "/usr/local/lib/python3.8/site-packages/django/template/loader_tags.py", line 62, in render
    result = block.nodelist.render(context)
  File "/usr/local/lib/python3.8/site-packages/django/template/base.py", line 938, in render
    bit = node.render_annotated(context)
  File "/usr/local/lib/python3.8/site-packages/django/template/base.py", line 905, in render_annotated
    return self.render(context)
  File "/usr/local/lib/python3.8/site-packages/django/template/defaulttags.py", line 168, in render
    len_values = len(values)
  File "/usr/local/lib/python3.8/site-packages/django/db/models/query.py", line 269, in __len__
    self._fetch_all()
  File "/usr/local/lib/python3.8/site-packages/django/db/models/query.py", line 1303, in _fetch_all
    self._result_cache = list(self._iterable_class(self))
  File "/usr/local/lib/python3.8/site-packages/django/db/models/query.py", line 53, in __iter__
    results = compiler.execute_sql(chunked_fetch=self.chunked_fetch, chunk_size=self.chunk_size)
  File "/usr/local/lib/python3.8/site-packages/django/db/models/sql/compiler.py", line 1156, in execute_sql
    cursor.execute(sql, params)
  File "/usr/local/lib/python3.8/site-packages/django/db/backends/utils.py", line 98, in execute
    return super().execute(sql, params)
  File "/usr/local/lib/python3.8/site-packages/django/db/backends/utils.py", line 66, in execute
    return self._execute_with_wrappers(sql, params, many=False, executor=self._execute)
  File "/usr/local/lib/python3.8/site-packages/django/db/backends/utils.py", line 75, in _execute_with_wrappers
    return executor(sql, params, many, context)
  File "/usr/local/lib/python3.8/site-packages/django/db/backends/utils.py", line 84, in _execute
    return self.cursor.execute(sql, params)
  File "/usr/local/lib/python3.8/site-packages/django/db/utils.py", line 90, in __exit__
    raise dj_exc_value.with_traceback(traceback) from exc_value
  File "/usr/local/lib/python3.8/site-packages/django/db/backends/utils.py", line 84, in _execute
    return self.cursor.execute(sql, params)
django.db.utils.ProgrammingError: relation "tech_mlmodel" does not exist
LINE 1: ... "tech_mlmodel"."mdl", "tech_mlmodel"."code" FROM "tech_mlmo...
                                                             ^

2020-10-20 00:53:53,613	[ERROR]	/usr/local/lib/python3.8/site-packages/django/core/servers/basehttp.py(Line:157)	"GET /tech/ HTTP/1.1" 500 192354
2020-10-20 00:54:18,654	[INFO]	/usr/local/lib/python3.8/site-packages/django/utils/autoreload.py(Line:612)	Watching for file changes with StatReloader
2020-10-20 00:54:47,594	[INFO]	/usr/local/lib/python3.8/site-packages/django/utils/autoreload.py(Line:612)	Watching for file changes with StatReloader
2020-10-20 00:59:51,991	[INFO]	/usr/local/lib/python3.8/site-packages/django/utils/autoreload.py(Line:612)	Watching for file changes with StatReloader
2020-10-20 01:10:04,692	[INFO]	/usr/local/lib/python3.8/site-packages/django/utils/autoreload.py(Line:236)	/code/MLkit/settings.py changed, reloading.
2020-10-20 01:10:05,252	[INFO]	/usr/local/lib/python3.8/site-packages/django/utils/autoreload.py(Line:612)	Watching for file changes with StatReloader
2020-10-20 01:10:28,665	[INFO]	/usr/local/lib/python3.8/site-packages/django/utils/autoreload.py(Line:612)	Watching for file changes with StatReloader
2020-10-20 01:20:20,975	[INFO]	/usr/local/lib/python3.8/site-packages/django/utils/autoreload.py(Line:236)	/code/MLkit/settings.py changed, reloading.
2020-10-20 01:20:21,602	[INFO]	/usr/local/lib/python3.8/site-packages/django/utils/autoreload.py(Line:612)	Watching for file changes with StatReloader
2020-10-20 01:20:39,932	[INFO]	/usr/local/lib/python3.8/site-packages/django/utils/autoreload.py(Line:612)	Watching for file changes with StatReloader
2020-10-20 01:25:41,992	[INFO]	/usr/local/lib/python3.8/site-packages/django/utils/autoreload.py(Line:236)	/code/MLkit/settings.py changed, reloading.
2020-10-20 01:25:42,535	[INFO]	/usr/local/lib/python3.8/site-packages/django/utils/autoreload.py(Line:612)	Watching for file changes with StatReloader
2020-10-20 01:28:43,714	[INFO]	/usr/local/lib/python3.8/site-packages/django/utils/autoreload.py(Line:612)	Watching for file changes with StatReloader
2020-10-20 01:30:36,300	[INFO]	/usr/local/lib/python3.8/site-packages/django/utils/autoreload.py(Line:612)	Watching for file changes with StatReloader
2020-10-20 01:31:40,133	[INFO]	/usr/local/lib/python3.8/site-packages/django/utils/autoreload.py(Line:612)	Watching for file changes with StatReloader
2020-10-20 01:35:06,156	[INFO]	/usr/local/lib/python3.8/site-packages/django/utils/autoreload.py(Line:236)	/code/MLkit/settings.py changed, reloading.
2020-10-20 01:37:56,925	[INFO]	/usr/local/lib/python3.8/site-packages/django/utils/autoreload.py(Line:612)	Watching for file changes with StatReloader
2020-10-20 01:52:16,187	[INFO]	/usr/local/lib/python3.8/site-packages/django/utils/autoreload.py(Line:612)	Watching for file changes with StatReloader
2020-10-20 01:52:38,859	[INFO]	/usr/local/lib/python3.8/site-packages/django/core/servers/basehttp.py(Line:157)	"GET /tech/ HTTP/1.1" 200 7148
2020-10-20 01:52:39,077	[INFO]	/usr/local/lib/python3.8/site-packages/django/core/servers/basehttp.py(Line:157)	"GET /static/img/favicon.png HTTP/1.1" 200 2761
2020-10-20 01:52:41,278	[INFO]	/usr/local/lib/python3.8/site-packages/django/core/servers/basehttp.py(Line:157)	"POST /tech/select_model HTTP/1.1" 302 0
2020-10-20 01:52:41,311	[INFO]	/usr/local/lib/python3.8/site-packages/django/core/servers/basehttp.py(Line:157)	"GET /tech/select_data HTTP/1.1" 200 7256
2020-10-20 01:54:53,180	[INFO]	/usr/local/lib/python3.8/site-packages/django/core/servers/basehttp.py(Line:157)	"POST /tech/select_data HTTP/1.1" 302 0
2020-10-20 01:54:53,207	[INFO]	/usr/local/lib/python3.8/site-packages/django/core/servers/basehttp.py(Line:157)	"GET /tech/calculation HTTP/1.1" 200 7211
2020-10-20 01:54:55,598	[INFO]	/usr/local/lib/python3.8/site-packages/django/core/servers/basehttp.py(Line:157)	"POST /tech/calculation HTTP/1.1" 200 6456
2020-10-20 01:54:59,706	[INFO]	/usr/local/lib/python3.8/site-packages/django/core/servers/basehttp.py(Line:157)	"GET /tech/help HTTP/1.1" 200 7719
2020-10-20 01:55:01,704	[INFO]	/usr/local/lib/python3.8/site-packages/django/core/servers/basehttp.py(Line:157)	"GET /tech/select_data HTTP/1.1" 200 7256
2020-10-20 01:55:23,354	[INFO]	/usr/local/lib/python3.8/site-packages/django/core/servers/basehttp.py(Line:157)	"POST /tech/select_data HTTP/1.1" 302 0
2020-10-20 01:55:23,382	[INFO]	/usr/local/lib/python3.8/site-packages/django/core/servers/basehttp.py(Line:157)	"GET /tech/calculation HTTP/1.1" 200 7212
2020-10-20 01:55:24,634	[INFO]	/usr/local/lib/python3.8/site-packages/django/core/servers/basehttp.py(Line:157)	"POST /tech/calculation HTTP/1.1" 302 0
2020-10-20 01:55:24,652	[INFO]	/usr/local/lib/python3.8/site-packages/django/core/servers/basehttp.py(Line:157)	"GET /tech/get_result HTTP/1.1" 200 7194
2020-10-20 01:55:26,328	[INFO]	/usr/local/lib/python3.8/site-packages/django/core/servers/basehttp.py(Line:157)	"POST /tech/calculation HTTP/1.1" 302 0
2020-10-20 01:55:26,345	[INFO]	/usr/local/lib/python3.8/site-packages/django/core/servers/basehttp.py(Line:157)	"GET /tech/get_result HTTP/1.1" 200 7194
2020-10-20 01:55:40,263	[INFO]	/usr/local/lib/python3.8/site-packages/django/core/servers/basehttp.py(Line:157)	"GET /tech/select_data? HTTP/1.1" 200 7256
2020-10-20 01:55:50,023	[INFO]	/usr/local/lib/python3.8/site-packages/django/core/servers/basehttp.py(Line:157)	"POST /tech/select_data HTTP/1.1" 302 0
2020-10-20 01:55:50,047	[INFO]	/usr/local/lib/python3.8/site-packages/django/core/servers/basehttp.py(Line:157)	"GET /tech/calculation HTTP/1.1" 200 7213
2020-10-20 01:55:51,577	[INFO]	/usr/local/lib/python3.8/site-packages/django/core/servers/basehttp.py(Line:157)	"POST /tech/calculation HTTP/1.1" 302 0
2020-10-20 01:55:51,594	[INFO]	/usr/local/lib/python3.8/site-packages/django/core/servers/basehttp.py(Line:157)	"GET /tech/get_result HTTP/1.1" 200 7194
2020-10-20 01:57:16,982	[INFO]	/usr/local/lib/python3.8/site-packages/django/utils/autoreload.py(Line:236)	/code/tech/views.py changed, reloading.
2020-10-20 01:57:17,512	[INFO]	/usr/local/lib/python3.8/site-packages/django/utils/autoreload.py(Line:612)	Watching for file changes with StatReloader
2020-10-20 02:00:52,347	[INFO]	/usr/local/lib/python3.8/site-packages/django/core/servers/basehttp.py(Line:157)	"GET /tech/select_data HTTP/1.1" 200 7256
2020-10-20 02:00:54,079	[INFO]	/usr/local/lib/python3.8/site-packages/django/core/servers/basehttp.py(Line:157)	"GET /tech/calculation HTTP/1.1" 200 7213
2020-10-20 02:00:55,680	[INFO]	/usr/local/lib/python3.8/site-packages/django/core/servers/basehttp.py(Line:157)	"POST /tech/calculation HTTP/1.1" 302 0
2020-10-20 02:00:55,697	[INFO]	/usr/local/lib/python3.8/site-packages/django/core/servers/basehttp.py(Line:157)	"GET /tech/get_result HTTP/1.1" 200 7194
2020-10-20 02:03:25,643	[INFO]	/usr/local/lib/python3.8/site-packages/django/utils/autoreload.py(Line:236)	/code/tech/views.py changed, reloading.
2020-10-20 02:03:26,357	[INFO]	/usr/local/lib/python3.8/site-packages/django/utils/autoreload.py(Line:612)	Watching for file changes with StatReloader
2020-10-20 02:03:34,699	[INFO]	/usr/local/lib/python3.8/site-packages/django/core/servers/basehttp.py(Line:157)	"GET /tech/calculation HTTP/1.1" 200 7213
2020-10-20 02:03:36,016	[INFO]	/usr/local/lib/python3.8/site-packages/django/core/servers/basehttp.py(Line:157)	"POST /tech/calculation HTTP/1.1" 302 0
2020-10-20 02:03:36,037	[INFO]	/usr/local/lib/python3.8/site-packages/django/core/servers/basehttp.py(Line:157)	"GET /tech/get_result HTTP/1.1" 200 7402
2020-10-20 02:03:40,057	[INFO]	/usr/local/lib/python3.8/site-packages/django/core/servers/basehttp.py(Line:157)	"POST /tech/get_result HTTP/1.1" 200 6384
2020-10-20 02:04:34,504	[INFO]	/usr/local/lib/python3.8/site-packages/django/core/servers/basehttp.py(Line:157)	"GET /tech/? HTTP/1.1" 200 7148
2020-10-20 02:04:38,791	[INFO]	/usr/local/lib/python3.8/site-packages/django/core/servers/basehttp.py(Line:157)	"POST /tech/select_model HTTP/1.1" 200 7300
2020-10-20 02:04:40,307	[INFO]	/usr/local/lib/python3.8/site-packages/django/core/servers/basehttp.py(Line:157)	"POST /tech/make_NN_model HTTP/1.1" 302 0
2020-10-20 02:04:40,330	[INFO]	/usr/local/lib/python3.8/site-packages/django/core/servers/basehttp.py(Line:157)	"GET /tech/select_data HTTP/1.1" 200 7256
2020-10-20 02:04:52,305	[INFO]	/usr/local/lib/python3.8/site-packages/django/core/servers/basehttp.py(Line:157)	"POST /tech/select_data HTTP/1.1" 302 0
2020-10-20 02:04:52,342	[INFO]	/usr/local/lib/python3.8/site-packages/django/core/servers/basehttp.py(Line:157)	"GET /tech/calculation HTTP/1.1" 200 7208
2020-10-20 02:04:54,398	[INFO]	/usr/local/lib/python3.8/site-packages/django/core/servers/basehttp.py(Line:157)	"POST /tech/calculation HTTP/1.1" 302 0
2020-10-20 02:04:54,415	[INFO]	/usr/local/lib/python3.8/site-packages/django/core/servers/basehttp.py(Line:157)	"GET /tech/get_result HTTP/1.1" 200 7402
2020-10-20 02:17:40,562	[INFO]	/usr/local/lib/python3.8/site-packages/django/core/servers/basehttp.py(Line:157)	"GET /tech/ HTTP/1.1" 200 7148
2020-10-20 02:17:43,091	[INFO]	/usr/local/lib/python3.8/site-packages/django/core/servers/basehttp.py(Line:157)	"GET /tech/select_model HTTP/1.1" 200 7148
2020-10-20 02:17:43,653	[INFO]	/usr/local/lib/python3.8/site-packages/django/core/servers/basehttp.py(Line:157)	"GET /tech/help HTTP/1.1" 200 7719
2020-10-20 02:17:45,825	[INFO]	/usr/local/lib/python3.8/site-packages/django/core/servers/basehttp.py(Line:157)	"POST /tech/help HTTP/1.1" 302 0
2020-10-20 02:18:16,472	[INFO]	/usr/local/lib/python3.8/site-packages/django/core/servers/basehttp.py(Line:157)	"GET /tech/help HTTP/1.1" 200 7719
2020-10-20 02:18:19,043	[INFO]	/usr/local/lib/python3.8/site-packages/django/core/servers/basehttp.py(Line:157)	"GET /tech/select_model HTTP/1.1" 200 7148
2020-10-20 02:18:24,061	[INFO]	/usr/local/lib/python3.8/site-packages/django/core/servers/basehttp.py(Line:157)	"POST /tech/select_model HTTP/1.1" 302 0
2020-10-20 02:18:24,080	[INFO]	/usr/local/lib/python3.8/site-packages/django/core/servers/basehttp.py(Line:157)	"GET /tech/select_data HTTP/1.1" 200 7256
2020-10-20 02:18:30,755	[INFO]	/usr/local/lib/python3.8/site-packages/django/core/servers/basehttp.py(Line:157)	"POST /tech/select_data HTTP/1.1" 302 0
2020-10-20 02:18:30,784	[INFO]	/usr/local/lib/python3.8/site-packages/django/core/servers/basehttp.py(Line:157)	"GET /tech/calculation HTTP/1.1" 200 7226
2020-10-20 02:18:32,096	[INFO]	/usr/local/lib/python3.8/site-packages/django/core/servers/basehttp.py(Line:157)	"POST /tech/calculation HTTP/1.1" 302 0
2020-10-20 02:18:32,113	[INFO]	/usr/local/lib/python3.8/site-packages/django/core/servers/basehttp.py(Line:157)	"GET /tech/get_result HTTP/1.1" 200 7402
2020-10-20 02:18:38,180	[WARNING]	/usr/local/lib/python3.8/site-packages/django/core/servers/basehttp.py(Line:157)	"GET /static/css/kit-free.css.map HTTP/1.1" 404 1686
2020-10-20 02:24:22,077	[INFO]	/usr/local/lib/python3.8/site-packages/django/utils/autoreload.py(Line:236)	/code/tech/views.py changed, reloading.
2020-10-20 02:24:22,688	[INFO]	/usr/local/lib/python3.8/site-packages/django/utils/autoreload.py(Line:612)	Watching for file changes with StatReloader
2020-10-20 02:24:26,400	[INFO]	/usr/local/lib/python3.8/site-packages/django/core/servers/basehttp.py(Line:157)	"GET /tech/calculation HTTP/1.1" 200 7226
2020-10-20 02:24:26,533	[WARNING]	/usr/local/lib/python3.8/site-packages/django/core/servers/basehttp.py(Line:157)	"GET /static/css/kit-free.css.map HTTP/1.1" 404 1686
2020-10-20 02:24:28,686	[INFO]	/usr/local/lib/python3.8/site-packages/django/core/servers/basehttp.py(Line:157)	"POST /tech/calculation HTTP/1.1" 200 7402
2020-10-20 02:24:28,764	[WARNING]	/usr/local/lib/python3.8/site-packages/django/core/servers/basehttp.py(Line:157)	"GET /static/css/kit-free.css.map HTTP/1.1" 404 1686
2020-10-20 02:24:52,377	[INFO]	/usr/local/lib/python3.8/site-packages/django/core/servers/basehttp.py(Line:157)	"GET /tech/calculation HTTP/1.1" 200 7226
2020-10-20 02:24:52,472	[WARNING]	/usr/local/lib/python3.8/site-packages/django/core/servers/basehttp.py(Line:157)	"GET /static/css/kit-free.css.map HTTP/1.1" 404 1686
2020-10-20 02:31:21,606	[INFO]	/usr/local/lib/python3.8/site-packages/django/core/servers/basehttp.py(Line:157)	"GET /tech/calculation HTTP/1.1" 200 7226
2020-10-20 02:31:21,694	[INFO]	/usr/local/lib/python3.8/site-packages/django/core/servers/basehttp.py(Line:157)	"GET /static/img/favicon.png HTTP/1.1" 200 2761
2020-10-20 02:31:23,268	[INFO]	/usr/local/lib/python3.8/site-packages/django/core/servers/basehttp.py(Line:157)	"POST /tech/calculation HTTP/1.1" 200 7402
2020-10-20 02:48:35,981	[INFO]	/usr/local/lib/python3.8/site-packages/django/utils/autoreload.py(Line:236)	/code/tech/views.py changed, reloading.
2020-10-20 02:48:36,667	[INFO]	/usr/local/lib/python3.8/site-packages/django/utils/autoreload.py(Line:612)	Watching for file changes with StatReloader
2020-10-20 02:48:47,613	[INFO]	/usr/local/lib/python3.8/site-packages/django/core/servers/basehttp.py(Line:157)	"GET /tech/calculation HTTP/1.1" 200 7226
2020-10-20 02:48:48,802	[INFO]	/usr/local/lib/python3.8/site-packages/django/core/servers/basehttp.py(Line:157)	"POST /tech/calculation HTTP/1.1" 200 7435
2020-10-20 02:48:54,271	[INFO]	/usr/local/lib/python3.8/site-packages/django/core/servers/basehttp.py(Line:157)	"GET /tech/? HTTP/1.1" 200 7148
2020-10-20 05:53:46,484	[INFO]	/usr/local/lib/python3.8/site-packages/django/utils/autoreload.py(Line:612)	Watching for file changes with StatReloader
2020-10-20 05:54:00,082	[ERROR]	/usr/local/lib/python3.8/site-packages/django/utils/log.py(Line:224)	Internal Server Error: /tech/
Traceback (most recent call last):
  File "/usr/local/lib/python3.8/site-packages/django/db/backends/utils.py", line 84, in _execute
    return self.cursor.execute(sql, params)
psycopg2.errors.UndefinedTable: relation "tech_mlmodel" does not exist
LINE 1: ... "tech_mlmodel"."mdl", "tech_mlmodel"."code" FROM "tech_mlmo...
                                                             ^


The above exception was the direct cause of the following exception:

Traceback (most recent call last):
  File "/usr/local/lib/python3.8/site-packages/django/core/handlers/exception.py", line 47, in inner
    response = get_response(request)
  File "/usr/local/lib/python3.8/site-packages/django/core/handlers/base.py", line 179, in _get_response
    response = wrapped_callback(request, *callback_args, **callback_kwargs)
  File "/code/tech/views.py", line 24, in index
    return render(request, "tech/index.html",{
  File "/usr/local/lib/python3.8/site-packages/django/shortcuts.py", line 19, in render
    content = loader.render_to_string(template_name, context, request, using=using)
  File "/usr/local/lib/python3.8/site-packages/django/template/loader.py", line 62, in render_to_string
    return template.render(context, request)
  File "/usr/local/lib/python3.8/site-packages/django/template/backends/django.py", line 61, in render
    return self.template.render(context)
  File "/usr/local/lib/python3.8/site-packages/django/template/base.py", line 170, in render
    return self._render(context)
  File "/usr/local/lib/python3.8/site-packages/django/template/base.py", line 162, in _render
    return self.nodelist.render(context)
  File "/usr/local/lib/python3.8/site-packages/django/template/base.py", line 938, in render
    bit = node.render_annotated(context)
  File "/usr/local/lib/python3.8/site-packages/django/template/base.py", line 905, in render_annotated
    return self.render(context)
  File "/usr/local/lib/python3.8/site-packages/django/template/loader_tags.py", line 150, in render
    return compiled_parent._render(context)
  File "/usr/local/lib/python3.8/site-packages/django/template/base.py", line 162, in _render
    return self.nodelist.render(context)
  File "/usr/local/lib/python3.8/site-packages/django/template/base.py", line 938, in render
    bit = node.render_annotated(context)
  File "/usr/local/lib/python3.8/site-packages/django/template/base.py", line 905, in render_annotated
    return self.render(context)
  File "/usr/local/lib/python3.8/site-packages/django/template/loader_tags.py", line 62, in render
    result = block.nodelist.render(context)
  File "/usr/local/lib/python3.8/site-packages/django/template/base.py", line 938, in render
    bit = node.render_annotated(context)
  File "/usr/local/lib/python3.8/site-packages/django/template/base.py", line 905, in render_annotated
    return self.render(context)
  File "/usr/local/lib/python3.8/site-packages/django/template/defaulttags.py", line 168, in render
    len_values = len(values)
  File "/usr/local/lib/python3.8/site-packages/django/db/models/query.py", line 269, in __len__
    self._fetch_all()
  File "/usr/local/lib/python3.8/site-packages/django/db/models/query.py", line 1303, in _fetch_all
    self._result_cache = list(self._iterable_class(self))
  File "/usr/local/lib/python3.8/site-packages/django/db/models/query.py", line 53, in __iter__
    results = compiler.execute_sql(chunked_fetch=self.chunked_fetch, chunk_size=self.chunk_size)
  File "/usr/local/lib/python3.8/site-packages/django/db/models/sql/compiler.py", line 1156, in execute_sql
    cursor.execute(sql, params)
  File "/usr/local/lib/python3.8/site-packages/django/db/backends/utils.py", line 98, in execute
    return super().execute(sql, params)
  File "/usr/local/lib/python3.8/site-packages/django/db/backends/utils.py", line 66, in execute
    return self._execute_with_wrappers(sql, params, many=False, executor=self._execute)
  File "/usr/local/lib/python3.8/site-packages/django/db/backends/utils.py", line 75, in _execute_with_wrappers
    return executor(sql, params, many, context)
  File "/usr/local/lib/python3.8/site-packages/django/db/backends/utils.py", line 84, in _execute
    return self.cursor.execute(sql, params)
  File "/usr/local/lib/python3.8/site-packages/django/db/utils.py", line 90, in __exit__
    raise dj_exc_value.with_traceback(traceback) from exc_value
  File "/usr/local/lib/python3.8/site-packages/django/db/backends/utils.py", line 84, in _execute
    return self.cursor.execute(sql, params)
django.db.utils.ProgrammingError: relation "tech_mlmodel" does not exist
LINE 1: ... "tech_mlmodel"."mdl", "tech_mlmodel"."code" FROM "tech_mlmo...
                                                             ^

2020-10-20 05:54:00,106	[ERROR]	/usr/local/lib/python3.8/site-packages/django/core/servers/basehttp.py(Line:157)	"GET /tech/? HTTP/1.1" 500 192365
2020-10-20 05:54:36,527	[INFO]	/usr/local/lib/python3.8/site-packages/django/utils/autoreload.py(Line:612)	Watching for file changes with StatReloader
2020-10-20 05:54:59,237	[ERROR]	/usr/local/lib/python3.8/site-packages/django/utils/log.py(Line:224)	Internal Server Error: /tech/
Traceback (most recent call last):
  File "/usr/local/lib/python3.8/site-packages/django/db/backends/utils.py", line 84, in _execute
    return self.cursor.execute(sql, params)
psycopg2.errors.UndefinedTable: relation "tech_mlmodel" does not exist
LINE 1: ... "tech_mlmodel"."mdl", "tech_mlmodel"."code" FROM "tech_mlmo...
                                                             ^


The above exception was the direct cause of the following exception:

Traceback (most recent call last):
  File "/usr/local/lib/python3.8/site-packages/django/core/handlers/exception.py", line 47, in inner
    response = get_response(request)
  File "/usr/local/lib/python3.8/site-packages/django/core/handlers/base.py", line 179, in _get_response
    response = wrapped_callback(request, *callback_args, **callback_kwargs)
  File "/code/tech/views.py", line 24, in index
    return render(request, "tech/index.html",{
  File "/usr/local/lib/python3.8/site-packages/django/shortcuts.py", line 19, in render
    content = loader.render_to_string(template_name, context, request, using=using)
  File "/usr/local/lib/python3.8/site-packages/django/template/loader.py", line 62, in render_to_string
    return template.render(context, request)
  File "/usr/local/lib/python3.8/site-packages/django/template/backends/django.py", line 61, in render
    return self.template.render(context)
  File "/usr/local/lib/python3.8/site-packages/django/template/base.py", line 170, in render
    return self._render(context)
  File "/usr/local/lib/python3.8/site-packages/django/template/base.py", line 162, in _render
    return self.nodelist.render(context)
  File "/usr/local/lib/python3.8/site-packages/django/template/base.py", line 938, in render
    bit = node.render_annotated(context)
  File "/usr/local/lib/python3.8/site-packages/django/template/base.py", line 905, in render_annotated
    return self.render(context)
  File "/usr/local/lib/python3.8/site-packages/django/template/loader_tags.py", line 150, in render
    return compiled_parent._render(context)
  File "/usr/local/lib/python3.8/site-packages/django/template/base.py", line 162, in _render
    return self.nodelist.render(context)
  File "/usr/local/lib/python3.8/site-packages/django/template/base.py", line 938, in render
    bit = node.render_annotated(context)
  File "/usr/local/lib/python3.8/site-packages/django/template/base.py", line 905, in render_annotated
    return self.render(context)
  File "/usr/local/lib/python3.8/site-packages/django/template/loader_tags.py", line 62, in render
    result = block.nodelist.render(context)
  File "/usr/local/lib/python3.8/site-packages/django/template/base.py", line 938, in render
    bit = node.render_annotated(context)
  File "/usr/local/lib/python3.8/site-packages/django/template/base.py", line 905, in render_annotated
    return self.render(context)
  File "/usr/local/lib/python3.8/site-packages/django/template/defaulttags.py", line 168, in render
    len_values = len(values)
  File "/usr/local/lib/python3.8/site-packages/django/db/models/query.py", line 269, in __len__
    self._fetch_all()
  File "/usr/local/lib/python3.8/site-packages/django/db/models/query.py", line 1303, in _fetch_all
    self._result_cache = list(self._iterable_class(self))
  File "/usr/local/lib/python3.8/site-packages/django/db/models/query.py", line 53, in __iter__
    results = compiler.execute_sql(chunked_fetch=self.chunked_fetch, chunk_size=self.chunk_size)
  File "/usr/local/lib/python3.8/site-packages/django/db/models/sql/compiler.py", line 1156, in execute_sql
    cursor.execute(sql, params)
  File "/usr/local/lib/python3.8/site-packages/django/db/backends/utils.py", line 98, in execute
    return super().execute(sql, params)
  File "/usr/local/lib/python3.8/site-packages/django/db/backends/utils.py", line 66, in execute
    return self._execute_with_wrappers(sql, params, many=False, executor=self._execute)
  File "/usr/local/lib/python3.8/site-packages/django/db/backends/utils.py", line 75, in _execute_with_wrappers
    return executor(sql, params, many, context)
  File "/usr/local/lib/python3.8/site-packages/django/db/backends/utils.py", line 84, in _execute
    return self.cursor.execute(sql, params)
  File "/usr/local/lib/python3.8/site-packages/django/db/utils.py", line 90, in __exit__
    raise dj_exc_value.with_traceback(traceback) from exc_value
  File "/usr/local/lib/python3.8/site-packages/django/db/backends/utils.py", line 84, in _execute
    return self.cursor.execute(sql, params)
django.db.utils.ProgrammingError: relation "tech_mlmodel" does not exist
LINE 1: ... "tech_mlmodel"."mdl", "tech_mlmodel"."code" FROM "tech_mlmo...
                                                             ^

2020-10-20 05:54:59,244	[ERROR]	/usr/local/lib/python3.8/site-packages/django/core/servers/basehttp.py(Line:157)	"GET /tech/ HTTP/1.1" 500 192061
2020-10-20 05:55:02,114	[ERROR]	/usr/local/lib/python3.8/site-packages/django/utils/log.py(Line:224)	Internal Server Error: /tech/
Traceback (most recent call last):
  File "/usr/local/lib/python3.8/site-packages/django/db/backends/utils.py", line 84, in _execute
    return self.cursor.execute(sql, params)
psycopg2.errors.UndefinedTable: relation "tech_mlmodel" does not exist
LINE 1: ... "tech_mlmodel"."mdl", "tech_mlmodel"."code" FROM "tech_mlmo...
                                                             ^


The above exception was the direct cause of the following exception:

Traceback (most recent call last):
  File "/usr/local/lib/python3.8/site-packages/django/core/handlers/exception.py", line 47, in inner
    response = get_response(request)
  File "/usr/local/lib/python3.8/site-packages/django/core/handlers/base.py", line 179, in _get_response
    response = wrapped_callback(request, *callback_args, **callback_kwargs)
  File "/code/tech/views.py", line 24, in index
    return render(request, "tech/index.html",{
  File "/usr/local/lib/python3.8/site-packages/django/shortcuts.py", line 19, in render
    content = loader.render_to_string(template_name, context, request, using=using)
  File "/usr/local/lib/python3.8/site-packages/django/template/loader.py", line 62, in render_to_string
    return template.render(context, request)
  File "/usr/local/lib/python3.8/site-packages/django/template/backends/django.py", line 61, in render
    return self.template.render(context)
  File "/usr/local/lib/python3.8/site-packages/django/template/base.py", line 170, in render
    return self._render(context)
  File "/usr/local/lib/python3.8/site-packages/django/template/base.py", line 162, in _render
    return self.nodelist.render(context)
  File "/usr/local/lib/python3.8/site-packages/django/template/base.py", line 938, in render
    bit = node.render_annotated(context)
  File "/usr/local/lib/python3.8/site-packages/django/template/base.py", line 905, in render_annotated
    return self.render(context)
  File "/usr/local/lib/python3.8/site-packages/django/template/loader_tags.py", line 150, in render
    return compiled_parent._render(context)
  File "/usr/local/lib/python3.8/site-packages/django/template/base.py", line 162, in _render
    return self.nodelist.render(context)
  File "/usr/local/lib/python3.8/site-packages/django/template/base.py", line 938, in render
    bit = node.render_annotated(context)
  File "/usr/local/lib/python3.8/site-packages/django/template/base.py", line 905, in render_annotated
    return self.render(context)
  File "/usr/local/lib/python3.8/site-packages/django/template/loader_tags.py", line 62, in render
    result = block.nodelist.render(context)
  File "/usr/local/lib/python3.8/site-packages/django/template/base.py", line 938, in render
    bit = node.render_annotated(context)
  File "/usr/local/lib/python3.8/site-packages/django/template/base.py", line 905, in render_annotated
    return self.render(context)
  File "/usr/local/lib/python3.8/site-packages/django/template/defaulttags.py", line 168, in render
    len_values = len(values)
  File "/usr/local/lib/python3.8/site-packages/django/db/models/query.py", line 269, in __len__
    self._fetch_all()
  File "/usr/local/lib/python3.8/site-packages/django/db/models/query.py", line 1303, in _fetch_all
    self._result_cache = list(self._iterable_class(self))
  File "/usr/local/lib/python3.8/site-packages/django/db/models/query.py", line 53, in __iter__
    results = compiler.execute_sql(chunked_fetch=self.chunked_fetch, chunk_size=self.chunk_size)
  File "/usr/local/lib/python3.8/site-packages/django/db/models/sql/compiler.py", line 1156, in execute_sql
    cursor.execute(sql, params)
  File "/usr/local/lib/python3.8/site-packages/django/db/backends/utils.py", line 98, in execute
    return super().execute(sql, params)
  File "/usr/local/lib/python3.8/site-packages/django/db/backends/utils.py", line 66, in execute
    return self._execute_with_wrappers(sql, params, many=False, executor=self._execute)
  File "/usr/local/lib/python3.8/site-packages/django/db/backends/utils.py", line 75, in _execute_with_wrappers
    return executor(sql, params, many, context)
  File "/usr/local/lib/python3.8/site-packages/django/db/backends/utils.py", line 84, in _execute
    return self.cursor.execute(sql, params)
  File "/usr/local/lib/python3.8/site-packages/django/db/utils.py", line 90, in __exit__
    raise dj_exc_value.with_traceback(traceback) from exc_value
  File "/usr/local/lib/python3.8/site-packages/django/db/backends/utils.py", line 84, in _execute
    return self.cursor.execute(sql, params)
django.db.utils.ProgrammingError: relation "tech_mlmodel" does not exist
LINE 1: ... "tech_mlmodel"."mdl", "tech_mlmodel"."code" FROM "tech_mlmo...
                                                             ^

2020-10-20 05:55:02,118	[ERROR]	/usr/local/lib/python3.8/site-packages/django/core/servers/basehttp.py(Line:157)	"GET /tech/ HTTP/1.1" 500 192198
2020-10-20 05:55:40,989	[INFO]	/usr/local/lib/python3.8/site-packages/django/utils/autoreload.py(Line:612)	Watching for file changes with StatReloader
2020-10-20 05:56:17,143	[ERROR]	/usr/local/lib/python3.8/site-packages/django/utils/log.py(Line:224)	Internal Server Error: /tech/
Traceback (most recent call last):
  File "/usr/local/lib/python3.8/site-packages/django/db/backends/utils.py", line 84, in _execute
    return self.cursor.execute(sql, params)
psycopg2.errors.UndefinedTable: relation "tech_mlmodel" does not exist
LINE 1: ... "tech_mlmodel"."mdl", "tech_mlmodel"."code" FROM "tech_mlmo...
                                                             ^


The above exception was the direct cause of the following exception:

Traceback (most recent call last):
  File "/usr/local/lib/python3.8/site-packages/django/core/handlers/exception.py", line 47, in inner
    response = get_response(request)
  File "/usr/local/lib/python3.8/site-packages/django/core/handlers/base.py", line 179, in _get_response
    response = wrapped_callback(request, *callback_args, **callback_kwargs)
  File "/code/tech/views.py", line 24, in index
    return render(request, "tech/index.html",{
  File "/usr/local/lib/python3.8/site-packages/django/shortcuts.py", line 19, in render
    content = loader.render_to_string(template_name, context, request, using=using)
  File "/usr/local/lib/python3.8/site-packages/django/template/loader.py", line 62, in render_to_string
    return template.render(context, request)
  File "/usr/local/lib/python3.8/site-packages/django/template/backends/django.py", line 61, in render
    return self.template.render(context)
  File "/usr/local/lib/python3.8/site-packages/django/template/base.py", line 170, in render
    return self._render(context)
  File "/usr/local/lib/python3.8/site-packages/django/template/base.py", line 162, in _render
    return self.nodelist.render(context)
  File "/usr/local/lib/python3.8/site-packages/django/template/base.py", line 938, in render
    bit = node.render_annotated(context)
  File "/usr/local/lib/python3.8/site-packages/django/template/base.py", line 905, in render_annotated
    return self.render(context)
  File "/usr/local/lib/python3.8/site-packages/django/template/loader_tags.py", line 150, in render
    return compiled_parent._render(context)
  File "/usr/local/lib/python3.8/site-packages/django/template/base.py", line 162, in _render
    return self.nodelist.render(context)
  File "/usr/local/lib/python3.8/site-packages/django/template/base.py", line 938, in render
    bit = node.render_annotated(context)
  File "/usr/local/lib/python3.8/site-packages/django/template/base.py", line 905, in render_annotated
    return self.render(context)
  File "/usr/local/lib/python3.8/site-packages/django/template/loader_tags.py", line 62, in render
    result = block.nodelist.render(context)
  File "/usr/local/lib/python3.8/site-packages/django/template/base.py", line 938, in render
    bit = node.render_annotated(context)
  File "/usr/local/lib/python3.8/site-packages/django/template/base.py", line 905, in render_annotated
    return self.render(context)
  File "/usr/local/lib/python3.8/site-packages/django/template/defaulttags.py", line 168, in render
    len_values = len(values)
  File "/usr/local/lib/python3.8/site-packages/django/db/models/query.py", line 269, in __len__
    self._fetch_all()
  File "/usr/local/lib/python3.8/site-packages/django/db/models/query.py", line 1303, in _fetch_all
    self._result_cache = list(self._iterable_class(self))
  File "/usr/local/lib/python3.8/site-packages/django/db/models/query.py", line 53, in __iter__
    results = compiler.execute_sql(chunked_fetch=self.chunked_fetch, chunk_size=self.chunk_size)
  File "/usr/local/lib/python3.8/site-packages/django/db/models/sql/compiler.py", line 1156, in execute_sql
    cursor.execute(sql, params)
  File "/usr/local/lib/python3.8/site-packages/django/db/backends/utils.py", line 98, in execute
    return super().execute(sql, params)
  File "/usr/local/lib/python3.8/site-packages/django/db/backends/utils.py", line 66, in execute
    return self._execute_with_wrappers(sql, params, many=False, executor=self._execute)
  File "/usr/local/lib/python3.8/site-packages/django/db/backends/utils.py", line 75, in _execute_with_wrappers
    return executor(sql, params, many, context)
  File "/usr/local/lib/python3.8/site-packages/django/db/backends/utils.py", line 84, in _execute
    return self.cursor.execute(sql, params)
  File "/usr/local/lib/python3.8/site-packages/django/db/utils.py", line 90, in __exit__
    raise dj_exc_value.with_traceback(traceback) from exc_value
  File "/usr/local/lib/python3.8/site-packages/django/db/backends/utils.py", line 84, in _execute
    return self.cursor.execute(sql, params)
django.db.utils.ProgrammingError: relation "tech_mlmodel" does not exist
LINE 1: ... "tech_mlmodel"."mdl", "tech_mlmodel"."code" FROM "tech_mlmo...
                                                             ^

2020-10-20 05:56:17,151	[ERROR]	/usr/local/lib/python3.8/site-packages/django/core/servers/basehttp.py(Line:157)	"GET /tech/ HTTP/1.1" 500 192198
2020-10-20 06:04:56,439	[INFO]	/usr/local/lib/python3.8/site-packages/django/utils/autoreload.py(Line:612)	Watching for file changes with StatReloader
2020-10-20 06:05:06,432	[INFO]	/usr/local/lib/python3.8/site-packages/django/core/servers/basehttp.py(Line:157)	"GET /tech/ HTTP/1.1" 200 7148
2020-10-20 06:05:06,557	[INFO]	/usr/local/lib/python3.8/site-packages/django/core/servers/basehttp.py(Line:157)	"GET /static/img/favicon.png HTTP/1.1" 200 2761
2020-10-20 07:04:46,042	[INFO]	/usr/local/lib/python3.8/site-packages/django/utils/autoreload.py(Line:612)	Watching for file changes with StatReloader
2020-10-20 07:05:40,385	[INFO]	/usr/local/lib/python3.8/site-packages/django/utils/autoreload.py(Line:612)	Watching for file changes with StatReloader
2020-10-20 07:12:21,169	[INFO]	/usr/local/lib/python3.8/site-packages/django/utils/autoreload.py(Line:612)	Watching for file changes with StatReloader
2020-10-20 09:04:42,367	[INFO]	/usr/local/lib/python3.8/site-packages/django/utils/autoreload.py(Line:612)	Watching for file changes with StatReloader
2020-10-20 09:05:28,103	[INFO]	/usr/local/lib/python3.8/site-packages/django/utils/autoreload.py(Line:612)	Watching for file changes with StatReloader
2020-10-21 02:03:55,185	[INFO]	/usr/local/lib/python3.8/site-packages/django/utils/autoreload.py(Line:612)	Watching for file changes with StatReloader
2020-10-21 02:05:45,040	[INFO]	/usr/local/lib/python3.8/site-packages/django/utils/autoreload.py(Line:612)	Watching for file changes with StatReloader
2020-10-21 02:10:56,142	[INFO]	/usr/local/lib/python3.8/site-packages/django/core/servers/basehttp.py(Line:157)	"POST /tech/select_model HTTP/1.1" 302 0
2020-10-21 02:10:56,175	[INFO]	/usr/local/lib/python3.8/site-packages/django/core/servers/basehttp.py(Line:157)	"GET /tech/select_data HTTP/1.1" 200 7256
2020-10-21 02:10:56,209	[INFO]	/usr/local/lib/python3.8/site-packages/django/core/servers/basehttp.py(Line:157)	"GET /static/css/my.css HTTP/1.1" 304 0
2020-10-21 02:10:56,210	[INFO]	/usr/local/lib/python3.8/site-packages/django/core/servers/basehttp.py(Line:157)	"GET /static/img/exam_img.jpg HTTP/1.1" 304 0
2020-10-21 02:10:56,227	[INFO]	/usr/local/lib/python3.8/site-packages/django/core/servers/basehttp.py(Line:157)	"GET /static/js/my/get_calculate.js HTTP/1.1" 304 0
2020-10-21 02:10:56,227	[INFO]	/usr/local/lib/python3.8/site-packages/django/core/servers/basehttp.py(Line:157)	"GET /static/js/my/get_model.js HTTP/1.1" 304 0
2020-10-21 02:11:06,291	[INFO]	/usr/local/lib/python3.8/site-packages/django/core/servers/basehttp.py(Line:157)	"POST /tech/select_data HTTP/1.1" 302 0
2020-10-21 02:11:06,313	[INFO]	/usr/local/lib/python3.8/site-packages/django/core/servers/basehttp.py(Line:157)	"GET /tech/calculation HTTP/1.1" 200 7210
2020-10-21 02:11:09,994	[ERROR]	/usr/local/lib/python3.8/site-packages/django/utils/log.py(Line:224)	Internal Server Error: /tech/calculation
Traceback (most recent call last):
  File "/usr/local/lib/python3.8/site-packages/django/core/handlers/exception.py", line 47, in inner
    response = get_response(request)
  File "/usr/local/lib/python3.8/site-packages/django/core/handlers/base.py", line 179, in _get_response
    response = wrapped_callback(request, *callback_args, **callback_kwargs)
  File "/code/tech/views.py", line 95, in calculation
    selected_mdl = eval(mlmodel)(data=selectedData.objects.last().data )
  File "/code/tech/calculations.py", line 29, in __init__
    data              = pd.read_csv(data).dropna()
  File "/usr/local/lib/python3.8/site-packages/pandas/io/parsers.py", line 686, in read_csv
    return _read(filepath_or_buffer, kwds)
  File "/usr/local/lib/python3.8/site-packages/pandas/io/parsers.py", line 452, in _read
    parser = TextFileReader(fp_or_buf, **kwds)
  File "/usr/local/lib/python3.8/site-packages/pandas/io/parsers.py", line 946, in __init__
    self._make_engine(self.engine)
  File "/usr/local/lib/python3.8/site-packages/pandas/io/parsers.py", line 1178, in _make_engine
    self._engine = CParserWrapper(self.f, **self.options)
  File "/usr/local/lib/python3.8/site-packages/pandas/io/parsers.py", line 2008, in __init__
    self._reader = parsers.TextReader(src, **kwds)
  File "pandas/_libs/parsers.pyx", line 537, in pandas._libs.parsers.TextReader.__cinit__
  File "pandas/_libs/parsers.pyx", line 740, in pandas._libs.parsers.TextReader._get_header
UnicodeDecodeError: 'utf-8' codec can't decode byte 0xff in position 0: invalid start byte
2020-10-21 02:11:10,007	[ERROR]	/usr/local/lib/python3.8/site-packages/django/core/servers/basehttp.py(Line:157)	"POST /tech/calculation HTTP/1.1" 500 127049
2020-10-21 02:11:13,016	[INFO]	/usr/local/lib/python3.8/site-packages/django/core/servers/basehttp.py(Line:157)	"GET /tech/select_data HTTP/1.1" 200 7256
2020-10-21 02:11:32,021	[INFO]	/usr/local/lib/python3.8/site-packages/django/core/servers/basehttp.py(Line:157)	"POST /tech/select_data HTTP/1.1" 302 0
2020-10-21 02:11:32,052	[INFO]	/usr/local/lib/python3.8/site-packages/django/core/servers/basehttp.py(Line:157)	"GET /tech/calculation HTTP/1.1" 200 7210
2020-10-21 02:11:33,460	[INFO]	/usr/local/lib/python3.8/site-packages/django/core/servers/basehttp.py(Line:157)	"POST /tech/calculation HTTP/1.1" 200 7437
2020-10-21 02:11:39,901	[INFO]	/usr/local/lib/python3.8/site-packages/django/core/servers/basehttp.py(Line:157)	"POST /tech/get_result HTTP/1.1" 200 6384
2020-10-21 02:11:43,321	[INFO]	/usr/local/lib/python3.8/site-packages/django/core/servers/basehttp.py(Line:157)	"GET /tech/? HTTP/1.1" 200 7148
2020-10-21 02:11:45,310	[INFO]	/usr/local/lib/python3.8/site-packages/django/core/servers/basehttp.py(Line:157)	"GET /tech/calculation HTTP/1.1" 200 7210
2020-10-21 02:11:46,621	[INFO]	/usr/local/lib/python3.8/site-packages/django/core/servers/basehttp.py(Line:157)	"GET /tech/select_data HTTP/1.1" 200 7256
2020-10-21 02:11:47,055	[INFO]	/usr/local/lib/python3.8/site-packages/django/core/servers/basehttp.py(Line:157)	"GET /tech/select_model HTTP/1.1" 200 7148
2020-10-21 02:11:47,493	[INFO]	/usr/local/lib/python3.8/site-packages/django/core/servers/basehttp.py(Line:157)	"GET /tech/help HTTP/1.1" 200 7719
2020-10-21 02:11:49,864	[INFO]	/usr/local/lib/python3.8/site-packages/django/core/servers/basehttp.py(Line:157)	"POST /tech/help HTTP/1.1" 302 0
2020-10-21 03:52:59,613	[INFO]	/usr/local/lib/python3.8/site-packages/django/utils/autoreload.py(Line:612)	Watching for file changes with StatReloader
2020-10-21 04:16:35,107	[INFO]	/usr/local/lib/python3.8/site-packages/django/core/servers/basehttp.py(Line:157)	"GET /tech/help HTTP/1.1" 200 7719
