2020-10-19 04:06:02,686	[INFO]	/usr/local/lib/python3.8/site-packages/django/utils/autoreload.py(Line:612)	Watching for file changes with StatReloader
2020-10-19 04:06:51,903	[INFO]	/usr/local/lib/python3.8/site-packages/django/utils/autoreload.py(Line:612)	Watching for file changes with StatReloader
2020-10-19 04:09:08,993	[INFO]	/usr/local/lib/python3.8/site-packages/django/utils/autoreload.py(Line:612)	Watching for file changes with StatReloader
2020-10-19 04:35:07,492	[INFO]	/usr/local/lib/python3.8/site-packages/django/utils/autoreload.py(Line:612)	Watching for file changes with StatReloader
2020-10-19 04:47:36,755	[INFO]	/usr/local/lib/python3.8/site-packages/django/utils/autoreload.py(Line:612)	Watching for file changes with StatReloader
2020-10-19 04:47:57,533	[INFO]	/usr/local/lib/python3.8/site-packages/django/core/servers/basehttp.py(Line:157)	"GET /tech/ HTTP/1.1" 200 6908
2020-10-19 04:47:57,594	[INFO]	/usr/local/lib/python3.8/site-packages/django/core/servers/basehttp.py(Line:157)	"GET /static/demo/demo.css HTTP/1.1" 304 0
2020-10-19 04:47:57,595	[INFO]	/usr/local/lib/python3.8/site-packages/django/core/servers/basehttp.py(Line:157)	"GET /static/css/material-kit.css HTTP/1.1" 304 0
2020-10-19 04:47:57,600	[INFO]	/usr/local/lib/python3.8/site-packages/django/core/servers/basehttp.py(Line:157)	"GET /static/css/my.css HTTP/1.1" 304 0
2020-10-19 04:47:57,601	[INFO]	/usr/local/lib/python3.8/site-packages/django/core/servers/basehttp.py(Line:157)	"GET /static/js/core/jquery.min.js HTTP/1.1" 304 0
2020-10-19 04:47:57,605	[INFO]	/usr/local/lib/python3.8/site-packages/django/core/servers/basehttp.py(Line:157)	"GET /static/js/core/popper.min.js HTTP/1.1" 304 0
2020-10-19 04:47:57,607	[INFO]	/usr/local/lib/python3.8/site-packages/django/core/servers/basehttp.py(Line:157)	"GET /static/js/core/bootstrap-material-design.min.js HTTP/1.1" 304 0
2020-10-19 04:47:57,616	[INFO]	/usr/local/lib/python3.8/site-packages/django/core/servers/basehttp.py(Line:157)	"GET /static/js/plugins/moment.min.js HTTP/1.1" 304 0
2020-10-19 04:47:57,617	[INFO]	/usr/local/lib/python3.8/site-packages/django/core/servers/basehttp.py(Line:157)	"GET /static/js/my/get_model.js HTTP/1.1" 304 0
2020-10-19 04:47:57,618	[INFO]	/usr/local/lib/python3.8/site-packages/django/core/servers/basehttp.py(Line:157)	"GET /static/js/my/get_calculate.js HTTP/1.1" 304 0
2020-10-19 04:47:57,619	[INFO]	/usr/local/lib/python3.8/site-packages/django/core/servers/basehttp.py(Line:157)	"GET /static/js/plugins/bootstrap-datetimepicker.js HTTP/1.1" 304 0
2020-10-19 04:47:57,621	[INFO]	/usr/local/lib/python3.8/site-packages/django/core/servers/basehttp.py(Line:157)	"GET /static/js/plugins/nouislider.min.js HTTP/1.1" 304 0
2020-10-19 04:47:57,654	[INFO]	/usr/local/lib/python3.8/site-packages/django/core/servers/basehttp.py(Line:157)	"GET /static/js/material-kit.js HTTP/1.1" 304 0
2020-10-19 04:47:57,688	[INFO]	/usr/local/lib/python3.8/site-packages/django/core/servers/basehttp.py(Line:157)	"GET /static/img/profile_city.jpg HTTP/1.1" 304 0
2020-10-19 04:47:57,753	[INFO]	/usr/local/lib/python3.8/site-packages/django/core/servers/basehttp.py(Line:157)	"GET /static/img/favicon.png HTTP/1.1" 200 2761
2020-10-19 04:51:54,825	[INFO]	/usr/local/lib/python3.8/site-packages/django/utils/autoreload.py(Line:612)	Watching for file changes with StatReloader
2020-10-19 04:52:07,714	[INFO]	/usr/local/lib/python3.8/site-packages/django/utils/autoreload.py(Line:236)	/code/MLkit/settings.py changed, reloading.
2020-10-19 04:52:08,525	[INFO]	/usr/local/lib/python3.8/site-packages/django/utils/autoreload.py(Line:612)	Watching for file changes with StatReloader
2020-10-19 04:52:19,755	[ERROR]	/usr/local/lib/python3.8/site-packages/django/utils/log.py(Line:224)	Internal Server Error: /tech/
Traceback (most recent call last):
  File "/usr/local/lib/python3.8/site-packages/django/db/backends/utils.py", line 84, in _execute
    return self.cursor.execute(sql, params)
psycopg2.errors.UndefinedTable: relation "tech_mlmodel" does not exist
LINE 1: ... "tech_mlmodel"."mdl", "tech_mlmodel"."code" FROM "tech_mlmo...
                                                             ^


The above exception was the direct cause of the following exception:

Traceback (most recent call last):
  File "/usr/local/lib/python3.8/site-packages/django/core/handlers/exception.py", line 47, in inner
    response = get_response(request)
  File "/usr/local/lib/python3.8/site-packages/django/core/handlers/base.py", line 179, in _get_response
    response = wrapped_callback(request, *callback_args, **callback_kwargs)
  File "/code/tech/views.py", line 24, in index
    return render(request, "tech/index.html",{
  File "/usr/local/lib/python3.8/site-packages/django/shortcuts.py", line 19, in render
    content = loader.render_to_string(template_name, context, request, using=using)
  File "/usr/local/lib/python3.8/site-packages/django/template/loader.py", line 62, in render_to_string
    return template.render(context, request)
  File "/usr/local/lib/python3.8/site-packages/django/template/backends/django.py", line 61, in render
    return self.template.render(context)
  File "/usr/local/lib/python3.8/site-packages/django/template/base.py", line 170, in render
    return self._render(context)
  File "/usr/local/lib/python3.8/site-packages/django/template/base.py", line 162, in _render
    return self.nodelist.render(context)
  File "/usr/local/lib/python3.8/site-packages/django/template/base.py", line 938, in render
    bit = node.render_annotated(context)
  File "/usr/local/lib/python3.8/site-packages/django/template/base.py", line 905, in render_annotated
    return self.render(context)
  File "/usr/local/lib/python3.8/site-packages/django/template/loader_tags.py", line 150, in render
    return compiled_parent._render(context)
  File "/usr/local/lib/python3.8/site-packages/django/template/base.py", line 162, in _render
    return self.nodelist.render(context)
  File "/usr/local/lib/python3.8/site-packages/django/template/base.py", line 938, in render
    bit = node.render_annotated(context)
  File "/usr/local/lib/python3.8/site-packages/django/template/base.py", line 905, in render_annotated
    return self.render(context)
  File "/usr/local/lib/python3.8/site-packages/django/template/loader_tags.py", line 62, in render
    result = block.nodelist.render(context)
  File "/usr/local/lib/python3.8/site-packages/django/template/base.py", line 938, in render
    bit = node.render_annotated(context)
  File "/usr/local/lib/python3.8/site-packages/django/template/base.py", line 905, in render_annotated
    return self.render(context)
  File "/usr/local/lib/python3.8/site-packages/django/template/defaulttags.py", line 168, in render
    len_values = len(values)
  File "/usr/local/lib/python3.8/site-packages/django/db/models/query.py", line 269, in __len__
    self._fetch_all()
  File "/usr/local/lib/python3.8/site-packages/django/db/models/query.py", line 1303, in _fetch_all
    self._result_cache = list(self._iterable_class(self))
  File "/usr/local/lib/python3.8/site-packages/django/db/models/query.py", line 53, in __iter__
    results = compiler.execute_sql(chunked_fetch=self.chunked_fetch, chunk_size=self.chunk_size)
  File "/usr/local/lib/python3.8/site-packages/django/db/models/sql/compiler.py", line 1156, in execute_sql
    cursor.execute(sql, params)
  File "/usr/local/lib/python3.8/site-packages/django/db/backends/utils.py", line 98, in execute
    return super().execute(sql, params)
  File "/usr/local/lib/python3.8/site-packages/django/db/backends/utils.py", line 66, in execute
    return self._execute_with_wrappers(sql, params, many=False, executor=self._execute)
  File "/usr/local/lib/python3.8/site-packages/django/db/backends/utils.py", line 75, in _execute_with_wrappers
    return executor(sql, params, many, context)
  File "/usr/local/lib/python3.8/site-packages/django/db/backends/utils.py", line 84, in _execute
    return self.cursor.execute(sql, params)
  File "/usr/local/lib/python3.8/site-packages/django/db/utils.py", line 90, in __exit__
    raise dj_exc_value.with_traceback(traceback) from exc_value
  File "/usr/local/lib/python3.8/site-packages/django/db/backends/utils.py", line 84, in _execute
    return self.cursor.execute(sql, params)
django.db.utils.ProgrammingError: relation "tech_mlmodel" does not exist
LINE 1: ... "tech_mlmodel"."mdl", "tech_mlmodel"."code" FROM "tech_mlmo...
                                                             ^

2020-10-19 04:52:19,955	[ERROR]	/usr/local/lib/python3.8/site-packages/django/core/servers/basehttp.py(Line:157)	"GET /tech/ HTTP/1.1" 500 192359
2020-10-19 04:55:11,039	[ERROR]	/usr/local/lib/python3.8/site-packages/django/utils/log.py(Line:224)	Internal Server Error: /tech/
Traceback (most recent call last):
  File "/usr/local/lib/python3.8/site-packages/django/db/backends/utils.py", line 84, in _execute
    return self.cursor.execute(sql, params)
psycopg2.errors.UndefinedTable: relation "tech_mlmodel" does not exist
LINE 1: ... "tech_mlmodel"."mdl", "tech_mlmodel"."code" FROM "tech_mlmo...
                                                             ^


The above exception was the direct cause of the following exception:

Traceback (most recent call last):
  File "/usr/local/lib/python3.8/site-packages/django/core/handlers/exception.py", line 47, in inner
    response = get_response(request)
  File "/usr/local/lib/python3.8/site-packages/django/core/handlers/base.py", line 179, in _get_response
    response = wrapped_callback(request, *callback_args, **callback_kwargs)
  File "/code/tech/views.py", line 24, in index
    return render(request, "tech/index.html",{
  File "/usr/local/lib/python3.8/site-packages/django/shortcuts.py", line 19, in render
    content = loader.render_to_string(template_name, context, request, using=using)
  File "/usr/local/lib/python3.8/site-packages/django/template/loader.py", line 62, in render_to_string
    return template.render(context, request)
  File "/usr/local/lib/python3.8/site-packages/django/template/backends/django.py", line 61, in render
    return self.template.render(context)
  File "/usr/local/lib/python3.8/site-packages/django/template/base.py", line 170, in render
    return self._render(context)
  File "/usr/local/lib/python3.8/site-packages/django/template/base.py", line 162, in _render
    return self.nodelist.render(context)
  File "/usr/local/lib/python3.8/site-packages/django/template/base.py", line 938, in render
    bit = node.render_annotated(context)
  File "/usr/local/lib/python3.8/site-packages/django/template/base.py", line 905, in render_annotated
    return self.render(context)
  File "/usr/local/lib/python3.8/site-packages/django/template/loader_tags.py", line 150, in render
    return compiled_parent._render(context)
  File "/usr/local/lib/python3.8/site-packages/django/template/base.py", line 162, in _render
    return self.nodelist.render(context)
  File "/usr/local/lib/python3.8/site-packages/django/template/base.py", line 938, in render
    bit = node.render_annotated(context)
  File "/usr/local/lib/python3.8/site-packages/django/template/base.py", line 905, in render_annotated
    return self.render(context)
  File "/usr/local/lib/python3.8/site-packages/django/template/loader_tags.py", line 62, in render
    result = block.nodelist.render(context)
  File "/usr/local/lib/python3.8/site-packages/django/template/base.py", line 938, in render
    bit = node.render_annotated(context)
  File "/usr/local/lib/python3.8/site-packages/django/template/base.py", line 905, in render_annotated
    return self.render(context)
  File "/usr/local/lib/python3.8/site-packages/django/template/defaulttags.py", line 168, in render
    len_values = len(values)
  File "/usr/local/lib/python3.8/site-packages/django/db/models/query.py", line 269, in __len__
    self._fetch_all()
  File "/usr/local/lib/python3.8/site-packages/django/db/models/query.py", line 1303, in _fetch_all
    self._result_cache = list(self._iterable_class(self))
  File "/usr/local/lib/python3.8/site-packages/django/db/models/query.py", line 53, in __iter__
    results = compiler.execute_sql(chunked_fetch=self.chunked_fetch, chunk_size=self.chunk_size)
  File "/usr/local/lib/python3.8/site-packages/django/db/models/sql/compiler.py", line 1156, in execute_sql
    cursor.execute(sql, params)
  File "/usr/local/lib/python3.8/site-packages/django/db/backends/utils.py", line 98, in execute
    return super().execute(sql, params)
  File "/usr/local/lib/python3.8/site-packages/django/db/backends/utils.py", line 66, in execute
    return self._execute_with_wrappers(sql, params, many=False, executor=self._execute)
  File "/usr/local/lib/python3.8/site-packages/django/db/backends/utils.py", line 75, in _execute_with_wrappers
    return executor(sql, params, many, context)
  File "/usr/local/lib/python3.8/site-packages/django/db/backends/utils.py", line 84, in _execute
    return self.cursor.execute(sql, params)
  File "/usr/local/lib/python3.8/site-packages/django/db/utils.py", line 90, in __exit__
    raise dj_exc_value.with_traceback(traceback) from exc_value
  File "/usr/local/lib/python3.8/site-packages/django/db/backends/utils.py", line 84, in _execute
    return self.cursor.execute(sql, params)
django.db.utils.ProgrammingError: relation "tech_mlmodel" does not exist
LINE 1: ... "tech_mlmodel"."mdl", "tech_mlmodel"."code" FROM "tech_mlmo...
                                                             ^

2020-10-19 04:55:11,041	[ERROR]	/usr/local/lib/python3.8/site-packages/django/core/servers/basehttp.py(Line:157)	"GET /tech/ HTTP/1.1" 500 192359
2020-10-19 04:55:20,775	[INFO]	/usr/local/lib/python3.8/site-packages/django/core/servers/basehttp.py(Line:157)	"GET /tech/select_data HTTP/1.1" 200 7256
2020-10-19 04:55:20,823	[INFO]	/usr/local/lib/python3.8/site-packages/django/core/servers/basehttp.py(Line:157)	"GET /static/img/exam_img.jpg HTTP/1.1" 304 0
2020-10-19 04:55:24,858	[ERROR]	/usr/local/lib/python3.8/site-packages/django/utils/log.py(Line:224)	Internal Server Error: /tech/
Traceback (most recent call last):
  File "/usr/local/lib/python3.8/site-packages/django/db/backends/utils.py", line 84, in _execute
    return self.cursor.execute(sql, params)
psycopg2.errors.UndefinedTable: relation "tech_mlmodel" does not exist
LINE 1: ... "tech_mlmodel"."mdl", "tech_mlmodel"."code" FROM "tech_mlmo...
                                                             ^


The above exception was the direct cause of the following exception:

Traceback (most recent call last):
  File "/usr/local/lib/python3.8/site-packages/django/core/handlers/exception.py", line 47, in inner
    response = get_response(request)
  File "/usr/local/lib/python3.8/site-packages/django/core/handlers/base.py", line 179, in _get_response
    response = wrapped_callback(request, *callback_args, **callback_kwargs)
  File "/code/tech/views.py", line 24, in index
    return render(request, "tech/index.html",{
  File "/usr/local/lib/python3.8/site-packages/django/shortcuts.py", line 19, in render
    content = loader.render_to_string(template_name, context, request, using=using)
  File "/usr/local/lib/python3.8/site-packages/django/template/loader.py", line 62, in render_to_string
    return template.render(context, request)
  File "/usr/local/lib/python3.8/site-packages/django/template/backends/django.py", line 61, in render
    return self.template.render(context)
  File "/usr/local/lib/python3.8/site-packages/django/template/base.py", line 170, in render
    return self._render(context)
  File "/usr/local/lib/python3.8/site-packages/django/template/base.py", line 162, in _render
    return self.nodelist.render(context)
  File "/usr/local/lib/python3.8/site-packages/django/template/base.py", line 938, in render
    bit = node.render_annotated(context)
  File "/usr/local/lib/python3.8/site-packages/django/template/base.py", line 905, in render_annotated
    return self.render(context)
  File "/usr/local/lib/python3.8/site-packages/django/template/loader_tags.py", line 150, in render
    return compiled_parent._render(context)
  File "/usr/local/lib/python3.8/site-packages/django/template/base.py", line 162, in _render
    return self.nodelist.render(context)
  File "/usr/local/lib/python3.8/site-packages/django/template/base.py", line 938, in render
    bit = node.render_annotated(context)
  File "/usr/local/lib/python3.8/site-packages/django/template/base.py", line 905, in render_annotated
    return self.render(context)
  File "/usr/local/lib/python3.8/site-packages/django/template/loader_tags.py", line 62, in render
    result = block.nodelist.render(context)
  File "/usr/local/lib/python3.8/site-packages/django/template/base.py", line 938, in render
    bit = node.render_annotated(context)
  File "/usr/local/lib/python3.8/site-packages/django/template/base.py", line 905, in render_annotated
    return self.render(context)
  File "/usr/local/lib/python3.8/site-packages/django/template/defaulttags.py", line 168, in render
    len_values = len(values)
  File "/usr/local/lib/python3.8/site-packages/django/db/models/query.py", line 269, in __len__
    self._fetch_all()
  File "/usr/local/lib/python3.8/site-packages/django/db/models/query.py", line 1303, in _fetch_all
    self._result_cache = list(self._iterable_class(self))
  File "/usr/local/lib/python3.8/site-packages/django/db/models/query.py", line 53, in __iter__
    results = compiler.execute_sql(chunked_fetch=self.chunked_fetch, chunk_size=self.chunk_size)
  File "/usr/local/lib/python3.8/site-packages/django/db/models/sql/compiler.py", line 1156, in execute_sql
    cursor.execute(sql, params)
  File "/usr/local/lib/python3.8/site-packages/django/db/backends/utils.py", line 98, in execute
    return super().execute(sql, params)
  File "/usr/local/lib/python3.8/site-packages/django/db/backends/utils.py", line 66, in execute
    return self._execute_with_wrappers(sql, params, many=False, executor=self._execute)
  File "/usr/local/lib/python3.8/site-packages/django/db/backends/utils.py", line 75, in _execute_with_wrappers
    return executor(sql, params, many, context)
  File "/usr/local/lib/python3.8/site-packages/django/db/backends/utils.py", line 84, in _execute
    return self.cursor.execute(sql, params)
  File "/usr/local/lib/python3.8/site-packages/django/db/utils.py", line 90, in __exit__
    raise dj_exc_value.with_traceback(traceback) from exc_value
  File "/usr/local/lib/python3.8/site-packages/django/db/backends/utils.py", line 84, in _execute
    return self.cursor.execute(sql, params)
django.db.utils.ProgrammingError: relation "tech_mlmodel" does not exist
LINE 1: ... "tech_mlmodel"."mdl", "tech_mlmodel"."code" FROM "tech_mlmo...
                                                             ^

2020-10-19 04:55:24,861	[ERROR]	/usr/local/lib/python3.8/site-packages/django/core/servers/basehttp.py(Line:157)	"GET /tech/ HTTP/1.1" 500 192229
2020-10-19 04:55:27,350	[ERROR]	/usr/local/lib/python3.8/site-packages/django/utils/log.py(Line:224)	Internal Server Error: /tech/select_model
Traceback (most recent call last):
  File "/usr/local/lib/python3.8/site-packages/django/db/backends/utils.py", line 84, in _execute
    return self.cursor.execute(sql, params)
psycopg2.errors.UndefinedTable: relation "tech_mlmodel" does not exist
LINE 1: ... "tech_mlmodel"."mdl", "tech_mlmodel"."code" FROM "tech_mlmo...
                                                             ^


The above exception was the direct cause of the following exception:

Traceback (most recent call last):
  File "/usr/local/lib/python3.8/site-packages/django/core/handlers/exception.py", line 47, in inner
    response = get_response(request)
  File "/usr/local/lib/python3.8/site-packages/django/core/handlers/base.py", line 179, in _get_response
    response = wrapped_callback(request, *callback_args, **callback_kwargs)
  File "/code/tech/views.py", line 46, in select_model
    return render(request, "tech/index.html" ,{
  File "/usr/local/lib/python3.8/site-packages/django/shortcuts.py", line 19, in render
    content = loader.render_to_string(template_name, context, request, using=using)
  File "/usr/local/lib/python3.8/site-packages/django/template/loader.py", line 62, in render_to_string
    return template.render(context, request)
  File "/usr/local/lib/python3.8/site-packages/django/template/backends/django.py", line 61, in render
    return self.template.render(context)
  File "/usr/local/lib/python3.8/site-packages/django/template/base.py", line 170, in render
    return self._render(context)
  File "/usr/local/lib/python3.8/site-packages/django/template/base.py", line 162, in _render
    return self.nodelist.render(context)
  File "/usr/local/lib/python3.8/site-packages/django/template/base.py", line 938, in render
    bit = node.render_annotated(context)
  File "/usr/local/lib/python3.8/site-packages/django/template/base.py", line 905, in render_annotated
    return self.render(context)
  File "/usr/local/lib/python3.8/site-packages/django/template/loader_tags.py", line 150, in render
    return compiled_parent._render(context)
  File "/usr/local/lib/python3.8/site-packages/django/template/base.py", line 162, in _render
    return self.nodelist.render(context)
  File "/usr/local/lib/python3.8/site-packages/django/template/base.py", line 938, in render
    bit = node.render_annotated(context)
  File "/usr/local/lib/python3.8/site-packages/django/template/base.py", line 905, in render_annotated
    return self.render(context)
  File "/usr/local/lib/python3.8/site-packages/django/template/loader_tags.py", line 62, in render
    result = block.nodelist.render(context)
  File "/usr/local/lib/python3.8/site-packages/django/template/base.py", line 938, in render
    bit = node.render_annotated(context)
  File "/usr/local/lib/python3.8/site-packages/django/template/base.py", line 905, in render_annotated
    return self.render(context)
  File "/usr/local/lib/python3.8/site-packages/django/template/defaulttags.py", line 168, in render
    len_values = len(values)
  File "/usr/local/lib/python3.8/site-packages/django/db/models/query.py", line 269, in __len__
    self._fetch_all()
  File "/usr/local/lib/python3.8/site-packages/django/db/models/query.py", line 1303, in _fetch_all
    self._result_cache = list(self._iterable_class(self))
  File "/usr/local/lib/python3.8/site-packages/django/db/models/query.py", line 53, in __iter__
    results = compiler.execute_sql(chunked_fetch=self.chunked_fetch, chunk_size=self.chunk_size)
  File "/usr/local/lib/python3.8/site-packages/django/db/models/sql/compiler.py", line 1156, in execute_sql
    cursor.execute(sql, params)
  File "/usr/local/lib/python3.8/site-packages/django/db/backends/utils.py", line 98, in execute
    return super().execute(sql, params)
  File "/usr/local/lib/python3.8/site-packages/django/db/backends/utils.py", line 66, in execute
    return self._execute_with_wrappers(sql, params, many=False, executor=self._execute)
  File "/usr/local/lib/python3.8/site-packages/django/db/backends/utils.py", line 75, in _execute_with_wrappers
    return executor(sql, params, many, context)
  File "/usr/local/lib/python3.8/site-packages/django/db/backends/utils.py", line 84, in _execute
    return self.cursor.execute(sql, params)
  File "/usr/local/lib/python3.8/site-packages/django/db/utils.py", line 90, in __exit__
    raise dj_exc_value.with_traceback(traceback) from exc_value
  File "/usr/local/lib/python3.8/site-packages/django/db/backends/utils.py", line 84, in _execute
    return self.cursor.execute(sql, params)
django.db.utils.ProgrammingError: relation "tech_mlmodel" does not exist
LINE 1: ... "tech_mlmodel"."mdl", "tech_mlmodel"."code" FROM "tech_mlmo...
                                                             ^

2020-10-19 04:55:27,352	[ERROR]	/usr/local/lib/python3.8/site-packages/django/core/servers/basehttp.py(Line:157)	"GET /tech/select_model HTTP/1.1" 500 192450
2020-10-19 04:55:32,399	[ERROR]	/usr/local/lib/python3.8/site-packages/django/utils/log.py(Line:224)	Internal Server Error: /tech/calculation
Traceback (most recent call last):
  File "/usr/local/lib/python3.8/site-packages/django/db/backends/utils.py", line 84, in _execute
    return self.cursor.execute(sql, params)
psycopg2.errors.UndefinedTable: relation "tech_selectedmodel" does not exist
LINE 1: SELECT (1) AS "a" FROM "tech_selectedmodel" LIMIT 1
                               ^


The above exception was the direct cause of the following exception:

Traceback (most recent call last):
  File "/usr/local/lib/python3.8/site-packages/django/core/handlers/exception.py", line 47, in inner
    response = get_response(request)
  File "/usr/local/lib/python3.8/site-packages/django/core/handlers/base.py", line 179, in _get_response
    response = wrapped_callback(request, *callback_args, **callback_kwargs)
  File "/code/tech/views.py", line 79, in calculation
    if selectedModel.objects.exists() and selectedData.objects.exists() :
  File "/usr/local/lib/python3.8/site-packages/django/db/models/manager.py", line 85, in manager_method
    return getattr(self.get_queryset(), name)(*args, **kwargs)
  File "/usr/local/lib/python3.8/site-packages/django/db/models/query.py", line 809, in exists
    return self.query.has_results(using=self.db)
  File "/usr/local/lib/python3.8/site-packages/django/db/models/sql/query.py", line 535, in has_results
    return compiler.has_results()
  File "/usr/local/lib/python3.8/site-packages/django/db/models/sql/compiler.py", line 1126, in has_results
    return bool(self.execute_sql(SINGLE))
  File "/usr/local/lib/python3.8/site-packages/django/db/models/sql/compiler.py", line 1156, in execute_sql
    cursor.execute(sql, params)
  File "/usr/local/lib/python3.8/site-packages/django/db/backends/utils.py", line 98, in execute
    return super().execute(sql, params)
  File "/usr/local/lib/python3.8/site-packages/django/db/backends/utils.py", line 66, in execute
    return self._execute_with_wrappers(sql, params, many=False, executor=self._execute)
  File "/usr/local/lib/python3.8/site-packages/django/db/backends/utils.py", line 75, in _execute_with_wrappers
    return executor(sql, params, many, context)
  File "/usr/local/lib/python3.8/site-packages/django/db/backends/utils.py", line 84, in _execute
    return self.cursor.execute(sql, params)
  File "/usr/local/lib/python3.8/site-packages/django/db/utils.py", line 90, in __exit__
    raise dj_exc_value.with_traceback(traceback) from exc_value
  File "/usr/local/lib/python3.8/site-packages/django/db/backends/utils.py", line 84, in _execute
    return self.cursor.execute(sql, params)
django.db.utils.ProgrammingError: relation "tech_selectedmodel" does not exist
LINE 1: SELECT (1) AS "a" FROM "tech_selectedmodel" LIMIT 1
                               ^

2020-10-19 04:55:32,402	[ERROR]	/usr/local/lib/python3.8/site-packages/django/core/servers/basehttp.py(Line:157)	"GET /tech/calculation HTTP/1.1" 500 112282
2020-10-19 04:56:32,091	[INFO]	/usr/local/lib/python3.8/site-packages/django/utils/autoreload.py(Line:612)	Watching for file changes with StatReloader
2020-10-19 04:57:20,470	[INFO]	/usr/local/lib/python3.8/site-packages/django/utils/autoreload.py(Line:612)	Watching for file changes with StatReloader
2020-10-19 04:58:05,421	[INFO]	/usr/local/lib/python3.8/site-packages/django/utils/autoreload.py(Line:612)	Watching for file changes with StatReloader
2020-10-19 04:59:29,769	[INFO]	/usr/local/lib/python3.8/site-packages/django/utils/autoreload.py(Line:612)	Watching for file changes with StatReloader
2020-10-19 05:03:04,234	[INFO]	/usr/local/lib/python3.8/site-packages/django/core/servers/basehttp.py(Line:157)	"GET /tech/ HTTP/1.1" 200 6838
2020-10-19 05:04:27,769	[INFO]	/usr/local/lib/python3.8/site-packages/django/core/servers/basehttp.py(Line:157)	"GET /tech/select_data HTTP/1.1" 200 7256
2020-10-19 05:04:29,704	[INFO]	/usr/local/lib/python3.8/site-packages/django/core/servers/basehttp.py(Line:157)	"GET /tech/calculation HTTP/1.1" 302 0
2020-10-19 05:04:29,722	[INFO]	/usr/local/lib/python3.8/site-packages/django/core/servers/basehttp.py(Line:157)	"GET /tech/empty HTTP/1.1" 200 6425
2020-10-19 05:04:31,433	[INFO]	/usr/local/lib/python3.8/site-packages/django/core/servers/basehttp.py(Line:157)	"GET /tech/help HTTP/1.1" 200 7389
2020-10-19 05:08:31,541	[INFO]	/usr/local/lib/python3.8/site-packages/django/utils/autoreload.py(Line:612)	Watching for file changes with StatReloader
2020-10-19 05:08:47,842	[INFO]	/usr/local/lib/python3.8/site-packages/django/core/servers/basehttp.py(Line:157)	"GET /tech/help HTTP/1.1" 200 7389
2020-10-19 05:08:47,926	[INFO]	/usr/local/lib/python3.8/site-packages/django/core/servers/basehttp.py(Line:157)	"GET /static/img/favicon.png HTTP/1.1" 200 2761
2020-10-19 05:08:49,757	[INFO]	/usr/local/lib/python3.8/site-packages/django/core/servers/basehttp.py(Line:157)	"GET /tech/help HTTP/1.1" 200 7389
2020-10-19 05:08:50,818	[INFO]	/usr/local/lib/python3.8/site-packages/django/core/servers/basehttp.py(Line:157)	"GET /tech/ HTTP/1.1" 200 6838
